INFO:     Will watch for changes in these directories: ['/workspace/orchestrator']
INFO:     Uvicorn running on http://127.0.0.1:8000 (Press CTRL+C to quit)
INFO:     Started reloader process [9765] using WatchFiles
INFO:     Started server process [9768]
INFO:     Waiting for application startup.
INFO:     Application startup complete.
ENV-CHECK: java:✔, aapt:✔, aapt2:✔, zipalign:✔, apksigner:✔, apktool:✔
INFO:     127.0.0.1:43722 - "GET /health HTTP/1.1" 200 OK
INFO:     127.0.0.1:50826 - "POST /tasks HTTP/1.1" 422 Unprocessable Content
INFO:     127.0.0.1:35648 - "GET /health HTTP/1.1" 200 OK
INFO:     127.0.0.1:60034 - "POST /tasks HTTP/1.1" 500 Internal Server Error
ERROR:    Exception in ASGI application
Traceback (most recent call last):
  File "/home/ubuntu/.local/lib/python3.13/site-packages/uvicorn/protocols/http/httptools_impl.py", line 401, in run_asgi
    result = await app(  # type: ignore[func-returns-value]
             ^^^^^^^^^^^^^^^^^^^^^^^^^^^^^^^^^^^^^^^^^^^^^^
        self.scope, self.receive, self.send
        ^^^^^^^^^^^^^^^^^^^^^^^^^^^^^^^^^^^
    )
    ^
  File "/home/ubuntu/.local/lib/python3.13/site-packages/uvicorn/middleware/proxy_headers.py", line 70, in __call__
    return await self.app(scope, receive, send)
           ^^^^^^^^^^^^^^^^^^^^^^^^^^^^^^^^^^^^
  File "/home/ubuntu/.local/lib/python3.13/site-packages/fastapi/applications.py", line 1054, in __call__
    await super().__call__(scope, receive, send)
  File "/home/ubuntu/.local/lib/python3.13/site-packages/starlette/applications.py", line 113, in __call__
    await self.middleware_stack(scope, receive, send)
  File "/home/ubuntu/.local/lib/python3.13/site-packages/starlette/middleware/errors.py", line 187, in __call__
    raise exc
  File "/home/ubuntu/.local/lib/python3.13/site-packages/starlette/middleware/errors.py", line 165, in __call__
    await self.app(scope, receive, _send)
  File "/home/ubuntu/.local/lib/python3.13/site-packages/starlette/middleware/exceptions.py", line 62, in __call__
    await wrap_app_handling_exceptions(self.app, conn)(scope, receive, send)
  File "/home/ubuntu/.local/lib/python3.13/site-packages/starlette/_exception_handler.py", line 62, in wrapped_app
    raise exc
  File "/home/ubuntu/.local/lib/python3.13/site-packages/starlette/_exception_handler.py", line 51, in wrapped_app
    await app(scope, receive, sender)
  File "/home/ubuntu/.local/lib/python3.13/site-packages/starlette/routing.py", line 715, in __call__
    await self.middleware_stack(scope, receive, send)
  File "/home/ubuntu/.local/lib/python3.13/site-packages/starlette/routing.py", line 735, in app
    await route.handle(scope, receive, send)
  File "/home/ubuntu/.local/lib/python3.13/site-packages/starlette/routing.py", line 288, in handle
    await self.app(scope, receive, send)
  File "/home/ubuntu/.local/lib/python3.13/site-packages/starlette/routing.py", line 76, in app
    await wrap_app_handling_exceptions(app, request)(scope, receive, send)
  File "/home/ubuntu/.local/lib/python3.13/site-packages/starlette/_exception_handler.py", line 62, in wrapped_app
    raise exc
  File "/home/ubuntu/.local/lib/python3.13/site-packages/starlette/_exception_handler.py", line 51, in wrapped_app
    await app(scope, receive, sender)
  File "/home/ubuntu/.local/lib/python3.13/site-packages/starlette/routing.py", line 73, in app
    response = await f(request)
               ^^^^^^^^^^^^^^^^
  File "/home/ubuntu/.local/lib/python3.13/site-packages/fastapi/routing.py", line 301, in app
    raw_response = await run_endpoint_function(
                   ^^^^^^^^^^^^^^^^^^^^^^^^^^^^
    ...<3 lines>...
    )
    ^
  File "/home/ubuntu/.local/lib/python3.13/site-packages/fastapi/routing.py", line 214, in run_endpoint_function
    return await run_in_threadpool(dependant.call, **values)
           ^^^^^^^^^^^^^^^^^^^^^^^^^^^^^^^^^^^^^^^^^^^^^^^^^
  File "/home/ubuntu/.local/lib/python3.13/site-packages/starlette/concurrency.py", line 39, in run_in_threadpool
    return await anyio.to_thread.run_sync(func, *args)
           ^^^^^^^^^^^^^^^^^^^^^^^^^^^^^^^^^^^^^^^^^^^
  File "/home/ubuntu/.local/lib/python3.13/site-packages/anyio/to_thread.py", line 56, in run_sync
    return await get_async_backend().run_sync_in_worker_thread(
           ^^^^^^^^^^^^^^^^^^^^^^^^^^^^^^^^^^^^^^^^^^^^^^^^^^^^
        func, args, abandon_on_cancel=abandon_on_cancel, limiter=limiter
        ^^^^^^^^^^^^^^^^^^^^^^^^^^^^^^^^^^^^^^^^^^^^^^^^^^^^^^^^^^^^^^^^
    )
    ^
  File "/home/ubuntu/.local/lib/python3.13/site-packages/anyio/_backends/_asyncio.py", line 2476, in run_sync_in_worker_thread
    return await future
           ^^^^^^^^^^^^
  File "/home/ubuntu/.local/lib/python3.13/site-packages/anyio/_backends/_asyncio.py", line 967, in run
    result = context.run(func, *args)
  File "/workspace/orchestrator/app.py", line 1985, in create_task
    if DB_ENABLED and DB:
       ^^^^^^^^^^
NameError: name 'DB_ENABLED' is not defined
INFO:     127.0.0.1:40752 - "POST /tasks HTTP/1.1" 500 Internal Server Error
ERROR:    Exception in ASGI application
Traceback (most recent call last):
  File "/home/ubuntu/.local/lib/python3.13/site-packages/uvicorn/protocols/http/httptools_impl.py", line 401, in run_asgi
    result = await app(  # type: ignore[func-returns-value]
             ^^^^^^^^^^^^^^^^^^^^^^^^^^^^^^^^^^^^^^^^^^^^^^
        self.scope, self.receive, self.send
        ^^^^^^^^^^^^^^^^^^^^^^^^^^^^^^^^^^^
    )
    ^
  File "/home/ubuntu/.local/lib/python3.13/site-packages/uvicorn/middleware/proxy_headers.py", line 70, in __call__
    return await self.app(scope, receive, send)
           ^^^^^^^^^^^^^^^^^^^^^^^^^^^^^^^^^^^^
  File "/home/ubuntu/.local/lib/python3.13/site-packages/fastapi/applications.py", line 1054, in __call__
    await super().__call__(scope, receive, send)
  File "/home/ubuntu/.local/lib/python3.13/site-packages/starlette/applications.py", line 113, in __call__
    await self.middleware_stack(scope, receive, send)
  File "/home/ubuntu/.local/lib/python3.13/site-packages/starlette/middleware/errors.py", line 187, in __call__
    raise exc
  File "/home/ubuntu/.local/lib/python3.13/site-packages/starlette/middleware/errors.py", line 165, in __call__
    await self.app(scope, receive, _send)
  File "/home/ubuntu/.local/lib/python3.13/site-packages/starlette/middleware/exceptions.py", line 62, in __call__
    await wrap_app_handling_exceptions(self.app, conn)(scope, receive, send)
  File "/home/ubuntu/.local/lib/python3.13/site-packages/starlette/_exception_handler.py", line 62, in wrapped_app
    raise exc
  File "/home/ubuntu/.local/lib/python3.13/site-packages/starlette/_exception_handler.py", line 51, in wrapped_app
    await app(scope, receive, sender)
  File "/home/ubuntu/.local/lib/python3.13/site-packages/starlette/routing.py", line 715, in __call__
    await self.middleware_stack(scope, receive, send)
  File "/home/ubuntu/.local/lib/python3.13/site-packages/starlette/routing.py", line 735, in app
    await route.handle(scope, receive, send)
  File "/home/ubuntu/.local/lib/python3.13/site-packages/starlette/routing.py", line 288, in handle
    await self.app(scope, receive, send)
  File "/home/ubuntu/.local/lib/python3.13/site-packages/starlette/routing.py", line 76, in app
    await wrap_app_handling_exceptions(app, request)(scope, receive, send)
  File "/home/ubuntu/.local/lib/python3.13/site-packages/starlette/_exception_handler.py", line 62, in wrapped_app
    raise exc
  File "/home/ubuntu/.local/lib/python3.13/site-packages/starlette/_exception_handler.py", line 51, in wrapped_app
    await app(scope, receive, sender)
  File "/home/ubuntu/.local/lib/python3.13/site-packages/starlette/routing.py", line 73, in app
    response = await f(request)
               ^^^^^^^^^^^^^^^^
  File "/home/ubuntu/.local/lib/python3.13/site-packages/fastapi/routing.py", line 301, in app
    raw_response = await run_endpoint_function(
                   ^^^^^^^^^^^^^^^^^^^^^^^^^^^^
    ...<3 lines>...
    )
    ^
  File "/home/ubuntu/.local/lib/python3.13/site-packages/fastapi/routing.py", line 214, in run_endpoint_function
    return await run_in_threadpool(dependant.call, **values)
           ^^^^^^^^^^^^^^^^^^^^^^^^^^^^^^^^^^^^^^^^^^^^^^^^^
  File "/home/ubuntu/.local/lib/python3.13/site-packages/starlette/concurrency.py", line 39, in run_in_threadpool
    return await anyio.to_thread.run_sync(func, *args)
           ^^^^^^^^^^^^^^^^^^^^^^^^^^^^^^^^^^^^^^^^^^^
  File "/home/ubuntu/.local/lib/python3.13/site-packages/anyio/to_thread.py", line 56, in run_sync
    return await get_async_backend().run_sync_in_worker_thread(
           ^^^^^^^^^^^^^^^^^^^^^^^^^^^^^^^^^^^^^^^^^^^^^^^^^^^^
        func, args, abandon_on_cancel=abandon_on_cancel, limiter=limiter
        ^^^^^^^^^^^^^^^^^^^^^^^^^^^^^^^^^^^^^^^^^^^^^^^^^^^^^^^^^^^^^^^^
    )
    ^
  File "/home/ubuntu/.local/lib/python3.13/site-packages/anyio/_backends/_asyncio.py", line 2476, in run_sync_in_worker_thread
    return await future
           ^^^^^^^^^^^^
  File "/home/ubuntu/.local/lib/python3.13/site-packages/anyio/_backends/_asyncio.py", line 967, in run
    result = context.run(func, *args)
  File "/workspace/orchestrator/app.py", line 1985, in create_task
    if DB_ENABLED and DB:
       ^^^^^^^^^^
NameError: name 'DB_ENABLED' is not defined
INFO:     127.0.0.1:59504 - "POST /tasks HTTP/1.1" 500 Internal Server Error
ERROR:    Exception in ASGI application
Traceback (most recent call last):
  File "/home/ubuntu/.local/lib/python3.13/site-packages/uvicorn/protocols/http/httptools_impl.py", line 401, in run_asgi
    result = await app(  # type: ignore[func-returns-value]
             ^^^^^^^^^^^^^^^^^^^^^^^^^^^^^^^^^^^^^^^^^^^^^^
        self.scope, self.receive, self.send
        ^^^^^^^^^^^^^^^^^^^^^^^^^^^^^^^^^^^
    )
    ^
  File "/home/ubuntu/.local/lib/python3.13/site-packages/uvicorn/middleware/proxy_headers.py", line 70, in __call__
    return await self.app(scope, receive, send)
           ^^^^^^^^^^^^^^^^^^^^^^^^^^^^^^^^^^^^
  File "/home/ubuntu/.local/lib/python3.13/site-packages/fastapi/applications.py", line 1054, in __call__
    await super().__call__(scope, receive, send)
  File "/home/ubuntu/.local/lib/python3.13/site-packages/starlette/applications.py", line 113, in __call__
    await self.middleware_stack(scope, receive, send)
  File "/home/ubuntu/.local/lib/python3.13/site-packages/starlette/middleware/errors.py", line 187, in __call__
    raise exc
  File "/home/ubuntu/.local/lib/python3.13/site-packages/starlette/middleware/errors.py", line 165, in __call__
    await self.app(scope, receive, _send)
  File "/home/ubuntu/.local/lib/python3.13/site-packages/starlette/middleware/exceptions.py", line 62, in __call__
    await wrap_app_handling_exceptions(self.app, conn)(scope, receive, send)
  File "/home/ubuntu/.local/lib/python3.13/site-packages/starlette/_exception_handler.py", line 62, in wrapped_app
    raise exc
  File "/home/ubuntu/.local/lib/python3.13/site-packages/starlette/_exception_handler.py", line 51, in wrapped_app
    await app(scope, receive, sender)
  File "/home/ubuntu/.local/lib/python3.13/site-packages/starlette/routing.py", line 715, in __call__
    await self.middleware_stack(scope, receive, send)
  File "/home/ubuntu/.local/lib/python3.13/site-packages/starlette/routing.py", line 735, in app
    await route.handle(scope, receive, send)
  File "/home/ubuntu/.local/lib/python3.13/site-packages/starlette/routing.py", line 288, in handle
    await self.app(scope, receive, send)
  File "/home/ubuntu/.local/lib/python3.13/site-packages/starlette/routing.py", line 76, in app
    await wrap_app_handling_exceptions(app, request)(scope, receive, send)
  File "/home/ubuntu/.local/lib/python3.13/site-packages/starlette/_exception_handler.py", line 62, in wrapped_app
    raise exc
  File "/home/ubuntu/.local/lib/python3.13/site-packages/starlette/_exception_handler.py", line 51, in wrapped_app
    await app(scope, receive, sender)
  File "/home/ubuntu/.local/lib/python3.13/site-packages/starlette/routing.py", line 73, in app
    response = await f(request)
               ^^^^^^^^^^^^^^^^
  File "/home/ubuntu/.local/lib/python3.13/site-packages/fastapi/routing.py", line 301, in app
    raw_response = await run_endpoint_function(
                   ^^^^^^^^^^^^^^^^^^^^^^^^^^^^
    ...<3 lines>...
    )
    ^
  File "/home/ubuntu/.local/lib/python3.13/site-packages/fastapi/routing.py", line 214, in run_endpoint_function
    return await run_in_threadpool(dependant.call, **values)
           ^^^^^^^^^^^^^^^^^^^^^^^^^^^^^^^^^^^^^^^^^^^^^^^^^
  File "/home/ubuntu/.local/lib/python3.13/site-packages/starlette/concurrency.py", line 39, in run_in_threadpool
    return await anyio.to_thread.run_sync(func, *args)
           ^^^^^^^^^^^^^^^^^^^^^^^^^^^^^^^^^^^^^^^^^^^
  File "/home/ubuntu/.local/lib/python3.13/site-packages/anyio/to_thread.py", line 56, in run_sync
    return await get_async_backend().run_sync_in_worker_thread(
           ^^^^^^^^^^^^^^^^^^^^^^^^^^^^^^^^^^^^^^^^^^^^^^^^^^^^
        func, args, abandon_on_cancel=abandon_on_cancel, limiter=limiter
        ^^^^^^^^^^^^^^^^^^^^^^^^^^^^^^^^^^^^^^^^^^^^^^^^^^^^^^^^^^^^^^^^
    )
    ^
  File "/home/ubuntu/.local/lib/python3.13/site-packages/anyio/_backends/_asyncio.py", line 2476, in run_sync_in_worker_thread
    return await future
           ^^^^^^^^^^^^
  File "/home/ubuntu/.local/lib/python3.13/site-packages/anyio/_backends/_asyncio.py", line 967, in run
    result = context.run(func, *args)
  File "/workspace/orchestrator/app.py", line 1985, in create_task
    if DB_ENABLED and DB:
       ^^^^^^^^^^
NameError: name 'DB_ENABLED' is not defined
WARNING:  WatchFiles detected changes in 'app.py'. Reloading...
INFO:     Shutting down
INFO:     Waiting for application shutdown.
INFO:     Application shutdown complete.
INFO:     Finished server process [9768]
INFO:     Started server process [14961]
INFO:     Waiting for application startup.
INFO:     Application startup complete.
WARNING:  WatchFiles detected changes in 'app.py'. Reloading...
INFO:     Shutting down
INFO:     Waiting for application shutdown.
INFO:     Application shutdown complete.
INFO:     Finished server process [14961]
INFO:     Started server process [15188]
INFO:     Waiting for application startup.
INFO:     Application startup complete.
ENV-CHECK: java:✔, aapt:✔, aapt2:✔, zipalign:✔, apksigner:✔, apktool:✔
INFO:     127.0.0.1:40116 - "POST /tasks HTTP/1.1" 500 Internal Server Error
ERROR:    Exception in ASGI application
Traceback (most recent call last):
  File "/home/ubuntu/.local/lib/python3.13/site-packages/uvicorn/protocols/http/httptools_impl.py", line 401, in run_asgi
    result = await app(  # type: ignore[func-returns-value]
             ^^^^^^^^^^^^^^^^^^^^^^^^^^^^^^^^^^^^^^^^^^^^^^
        self.scope, self.receive, self.send
        ^^^^^^^^^^^^^^^^^^^^^^^^^^^^^^^^^^^
    )
    ^
  File "/home/ubuntu/.local/lib/python3.13/site-packages/uvicorn/middleware/proxy_headers.py", line 70, in __call__
    return await self.app(scope, receive, send)
           ^^^^^^^^^^^^^^^^^^^^^^^^^^^^^^^^^^^^
  File "/home/ubuntu/.local/lib/python3.13/site-packages/fastapi/applications.py", line 1054, in __call__
    await super().__call__(scope, receive, send)
  File "/home/ubuntu/.local/lib/python3.13/site-packages/starlette/applications.py", line 113, in __call__
    await self.middleware_stack(scope, receive, send)
  File "/home/ubuntu/.local/lib/python3.13/site-packages/starlette/middleware/errors.py", line 187, in __call__
    raise exc
  File "/home/ubuntu/.local/lib/python3.13/site-packages/starlette/middleware/errors.py", line 165, in __call__
    await self.app(scope, receive, _send)
  File "/home/ubuntu/.local/lib/python3.13/site-packages/starlette/middleware/exceptions.py", line 62, in __call__
    await wrap_app_handling_exceptions(self.app, conn)(scope, receive, send)
  File "/home/ubuntu/.local/lib/python3.13/site-packages/starlette/_exception_handler.py", line 62, in wrapped_app
    raise exc
  File "/home/ubuntu/.local/lib/python3.13/site-packages/starlette/_exception_handler.py", line 51, in wrapped_app
    await app(scope, receive, sender)
  File "/home/ubuntu/.local/lib/python3.13/site-packages/starlette/routing.py", line 715, in __call__
    await self.middleware_stack(scope, receive, send)
  File "/home/ubuntu/.local/lib/python3.13/site-packages/starlette/routing.py", line 735, in app
    await route.handle(scope, receive, send)
  File "/home/ubuntu/.local/lib/python3.13/site-packages/starlette/routing.py", line 288, in handle
    await self.app(scope, receive, send)
  File "/home/ubuntu/.local/lib/python3.13/site-packages/starlette/routing.py", line 76, in app
    await wrap_app_handling_exceptions(app, request)(scope, receive, send)
  File "/home/ubuntu/.local/lib/python3.13/site-packages/starlette/_exception_handler.py", line 62, in wrapped_app
    raise exc
  File "/home/ubuntu/.local/lib/python3.13/site-packages/starlette/_exception_handler.py", line 51, in wrapped_app
    await app(scope, receive, sender)
  File "/home/ubuntu/.local/lib/python3.13/site-packages/starlette/routing.py", line 73, in app
    response = await f(request)
               ^^^^^^^^^^^^^^^^
  File "/home/ubuntu/.local/lib/python3.13/site-packages/fastapi/routing.py", line 301, in app
    raw_response = await run_endpoint_function(
                   ^^^^^^^^^^^^^^^^^^^^^^^^^^^^
    ...<3 lines>...
    )
    ^
  File "/home/ubuntu/.local/lib/python3.13/site-packages/fastapi/routing.py", line 214, in run_endpoint_function
    return await run_in_threadpool(dependant.call, **values)
           ^^^^^^^^^^^^^^^^^^^^^^^^^^^^^^^^^^^^^^^^^^^^^^^^^
  File "/home/ubuntu/.local/lib/python3.13/site-packages/starlette/concurrency.py", line 39, in run_in_threadpool
    return await anyio.to_thread.run_sync(func, *args)
           ^^^^^^^^^^^^^^^^^^^^^^^^^^^^^^^^^^^^^^^^^^^
  File "/home/ubuntu/.local/lib/python3.13/site-packages/anyio/to_thread.py", line 56, in run_sync
    return await get_async_backend().run_sync_in_worker_thread(
           ^^^^^^^^^^^^^^^^^^^^^^^^^^^^^^^^^^^^^^^^^^^^^^^^^^^^
        func, args, abandon_on_cancel=abandon_on_cancel, limiter=limiter
        ^^^^^^^^^^^^^^^^^^^^^^^^^^^^^^^^^^^^^^^^^^^^^^^^^^^^^^^^^^^^^^^^
    )
    ^
  File "/home/ubuntu/.local/lib/python3.13/site-packages/anyio/_backends/_asyncio.py", line 2476, in run_sync_in_worker_thread
    return await future
           ^^^^^^^^^^^^
  File "/home/ubuntu/.local/lib/python3.13/site-packages/anyio/_backends/_asyncio.py", line 967, in run
    result = context.run(func, *args)
  File "/workspace/orchestrator/app.py", line 1985, in create_task
    if DB_ENABLED and DB:
       ^^^^^^^^^^
NameError: name 'DB_ENABLED' is not defined
INFO:     127.0.0.1:47068 - "POST /tasks HTTP/1.1" 500 Internal Server Error
ERROR:    Exception in ASGI application
Traceback (most recent call last):
  File "/home/ubuntu/.local/lib/python3.13/site-packages/uvicorn/protocols/http/httptools_impl.py", line 401, in run_asgi
    result = await app(  # type: ignore[func-returns-value]
             ^^^^^^^^^^^^^^^^^^^^^^^^^^^^^^^^^^^^^^^^^^^^^^
        self.scope, self.receive, self.send
        ^^^^^^^^^^^^^^^^^^^^^^^^^^^^^^^^^^^
    )
    ^
  File "/home/ubuntu/.local/lib/python3.13/site-packages/uvicorn/middleware/proxy_headers.py", line 70, in __call__
    return await self.app(scope, receive, send)
           ^^^^^^^^^^^^^^^^^^^^^^^^^^^^^^^^^^^^
  File "/home/ubuntu/.local/lib/python3.13/site-packages/fastapi/applications.py", line 1054, in __call__
    await super().__call__(scope, receive, send)
  File "/home/ubuntu/.local/lib/python3.13/site-packages/starlette/applications.py", line 113, in __call__
    await self.middleware_stack(scope, receive, send)
  File "/home/ubuntu/.local/lib/python3.13/site-packages/starlette/middleware/errors.py", line 187, in __call__
    raise exc
  File "/home/ubuntu/.local/lib/python3.13/site-packages/starlette/middleware/errors.py", line 165, in __call__
    await self.app(scope, receive, _send)
  File "/home/ubuntu/.local/lib/python3.13/site-packages/starlette/middleware/exceptions.py", line 62, in __call__
    await wrap_app_handling_exceptions(self.app, conn)(scope, receive, send)
  File "/home/ubuntu/.local/lib/python3.13/site-packages/starlette/_exception_handler.py", line 62, in wrapped_app
    raise exc
  File "/home/ubuntu/.local/lib/python3.13/site-packages/starlette/_exception_handler.py", line 51, in wrapped_app
    await app(scope, receive, sender)
  File "/home/ubuntu/.local/lib/python3.13/site-packages/starlette/routing.py", line 715, in __call__
    await self.middleware_stack(scope, receive, send)
  File "/home/ubuntu/.local/lib/python3.13/site-packages/starlette/routing.py", line 735, in app
    await route.handle(scope, receive, send)
  File "/home/ubuntu/.local/lib/python3.13/site-packages/starlette/routing.py", line 288, in handle
    await self.app(scope, receive, send)
  File "/home/ubuntu/.local/lib/python3.13/site-packages/starlette/routing.py", line 76, in app
    await wrap_app_handling_exceptions(app, request)(scope, receive, send)
  File "/home/ubuntu/.local/lib/python3.13/site-packages/starlette/_exception_handler.py", line 62, in wrapped_app
    raise exc
  File "/home/ubuntu/.local/lib/python3.13/site-packages/starlette/_exception_handler.py", line 51, in wrapped_app
    await app(scope, receive, sender)
  File "/home/ubuntu/.local/lib/python3.13/site-packages/starlette/routing.py", line 73, in app
    response = await f(request)
               ^^^^^^^^^^^^^^^^
  File "/home/ubuntu/.local/lib/python3.13/site-packages/fastapi/routing.py", line 301, in app
    raw_response = await run_endpoint_function(
                   ^^^^^^^^^^^^^^^^^^^^^^^^^^^^
    ...<3 lines>...
    )
    ^
  File "/home/ubuntu/.local/lib/python3.13/site-packages/fastapi/routing.py", line 214, in run_endpoint_function
    return await run_in_threadpool(dependant.call, **values)
           ^^^^^^^^^^^^^^^^^^^^^^^^^^^^^^^^^^^^^^^^^^^^^^^^^
  File "/home/ubuntu/.local/lib/python3.13/site-packages/starlette/concurrency.py", line 39, in run_in_threadpool
    return await anyio.to_thread.run_sync(func, *args)
           ^^^^^^^^^^^^^^^^^^^^^^^^^^^^^^^^^^^^^^^^^^^
  File "/home/ubuntu/.local/lib/python3.13/site-packages/anyio/to_thread.py", line 56, in run_sync
    return await get_async_backend().run_sync_in_worker_thread(
           ^^^^^^^^^^^^^^^^^^^^^^^^^^^^^^^^^^^^^^^^^^^^^^^^^^^^
        func, args, abandon_on_cancel=abandon_on_cancel, limiter=limiter
        ^^^^^^^^^^^^^^^^^^^^^^^^^^^^^^^^^^^^^^^^^^^^^^^^^^^^^^^^^^^^^^^^
    )
    ^
  File "/home/ubuntu/.local/lib/python3.13/site-packages/anyio/_backends/_asyncio.py", line 2476, in run_sync_in_worker_thread
    return await future
           ^^^^^^^^^^^^
  File "/home/ubuntu/.local/lib/python3.13/site-packages/anyio/_backends/_asyncio.py", line 967, in run
    result = context.run(func, *args)
  File "/workspace/orchestrator/app.py", line 1985, in create_task
    if DB_ENABLED and DB:
       ^^^^^^^^^^
NameError: name 'DB_ENABLED' is not defined
WARNING:  WatchFiles detected changes in 'app.py'. Reloading...
INFO:     Shutting down
INFO:     Waiting for application shutdown.
INFO:     Application shutdown complete.
INFO:     Finished server process [15188]
INFO:     Started server process [16507]
INFO:     Waiting for application startup.
INFO:     Application startup complete.
WARNING:  WatchFiles detected changes in 'app.py'. Reloading...
INFO:     Shutting down
INFO:     Waiting for application shutdown.
INFO:     Application shutdown complete.
INFO:     Finished server process [16507]
INFO:     Started server process [16735]
INFO:     Waiting for application startup.
INFO:     Application startup complete.
ENV-CHECK: java:✔, aapt:✔, aapt2:✔, zipalign:✔, apksigner:✔, apktool:✔
INFO:     127.0.0.1:60858 - "POST /tasks HTTP/1.1" 200 OK
Exception in thread Thread-2 (runner):
Traceback (most recent call last):
  File "/usr/lib/python3.13/threading.py", line 1041, in _bootstrap_inner
    self.run()
    ~~~~~~~~^^
  File "/usr/lib/python3.13/threading.py", line 992, in run
    self._target(*self._args, **self._kwargs)
    ~~~~~~~~~~~~^^^^^^^^^^^^^^^^^^^^^^^^^^^^^
  File "/workspace/orchestrator/app.py", line 2011, in runner
    run_listener_task(t.id, base, t.params)
    ~~~~~~~~~~~~~~~~~^^^^^^^^^^^^^^^^^^^^^^
  File "/workspace/orchestrator/app.py", line 1649, in run_listener_task
    rc = _spawn(cmd, run_log)
  File "/workspace/orchestrator/app.py", line 1528, in _spawn
    proc = subprocess.Popen(cmd, stdout=lf, stderr=subprocess.STDOUT, cwd=str(cwd) if cwd else None, env=env)
  File "/usr/lib/python3.13/subprocess.py", line 1039, in __init__
    self._execute_child(args, executable, preexec_fn, close_fds,
    ~~~~~~~~~~~~~~~~~~~^^^^^^^^^^^^^^^^^^^^^^^^^^^^^^^^^^^^^^^^^
                        pass_fds, cwd, env,
                        ^^^^^^^^^^^^^^^^^^^
    ...<5 lines>...
                        gid, gids, uid, umask,
                        ^^^^^^^^^^^^^^^^^^^^^^
                        start_new_session, process_group)
                        ^^^^^^^^^^^^^^^^^^^^^^^^^^^^^^^^^
  File "/usr/lib/python3.13/subprocess.py", line 1969, in _execute_child
    raise child_exception_type(errno_num, err_msg, err_filename)
FileNotFoundError: [Errno 2] No such file or directory: 'msfconsole'
INFO:     127.0.0.1:60864 - "GET /tasks/57f77879-listener HTTP/1.1" 200 OK
INFO:     127.0.0.1:60864 - "GET /tasks/57f77879-listener HTTP/1.1" 200 OK
INFO:     127.0.0.1:60864 - "GET /tasks/57f77879-listener HTTP/1.1" 200 OK
INFO:     127.0.0.1:48290 - "GET /tasks/57f77879-listener HTTP/1.1" 200 OK
INFO:     127.0.0.1:35946 - "GET /tasks/57f77879-listener HTTP/1.1" 200 OK
INFO:     127.0.0.1:50036 - "GET /health HTTP/1.1" 200 OK
INFO:     127.0.0.1:57748 - "GET /tasks/57f77879-listener HTTP/1.1" 200 OK
INFO:     127.0.0.1:35388 - "GET /tasks/57f77879-listener HTTP/1.1" 200 OK
WARNING:  WatchFiles detected changes in 'app.py'. Reloading...
INFO:     Shutting down
INFO:     Waiting for application shutdown.
INFO:     Application shutdown complete.
INFO:     Finished server process [16735]
INFO:     Started server process [17617]
INFO:     Waiting for application startup.
INFO:     Application startup complete.
WARNING:  WatchFiles detected changes in 'app.py'. Reloading...
INFO:     Shutting down
INFO:     Waiting for application shutdown.
INFO:     Application shutdown complete.
INFO:     Finished server process [17617]
INFO:     Started server process [17791]
INFO:     Waiting for application startup.
INFO:     Application startup complete.
ENV-CHECK: java:✔, aapt:✔, aapt2:✔, zipalign:✔, apksigner:✔, apktool:✔
INFO:     127.0.0.1:35198 - "GET /tasks/57f77879-listener HTTP/1.1" 404 Not Found
INFO:     127.0.0.1:41946 - "POST /tasks HTTP/1.1" 200 OK
Exception in thread Thread-2 (runner):
Traceback (most recent call last):
  File "/usr/lib/python3.13/threading.py", line 1041, in _bootstrap_inner
    self.run()
    ~~~~~~~~^^
  File "/usr/lib/python3.13/threading.py", line 992, in run
    self._target(*self._args, **self._kwargs)
    ~~~~~~~~~~~~^^^^^^^^^^^^^^^^^^^^^^^^^^^^^
  File "/workspace/orchestrator/app.py", line 2020, in runner
    run_listener_task(t.id, base, t.params)
    ~~~~~~~~~~~~~~~~~^^^^^^^^^^^^^^^^^^^^^^
  File "/workspace/orchestrator/app.py", line 1658, in run_listener_task
    rc = _spawn(cmd, run_log) if not USE_DOCKER else _spawn_container_sh("msfconsole -qx 'resource output/handler.rc; sleep 2; jobs; exit -y'", run_log, base)
                                                     ~~~~~~~~~~~~~~~~~~~^^^^^^^^^^^^^^^^^^^^^^^^^^^^^^^^^^^^^^^^^^^^^^^^^^^^^^^^^^^^^^^^^^^^^^^^^^^^^^^^^^^^^^
  File "/workspace/orchestrator/app.py", line 1542, in _spawn_container_sh
    proc = subprocess.Popen(
        ["docker", "run", "--rm", "-v", f"{task_home}:/workspace", "-v", f"{log_path.parent}:/logs", DOCKER_IMAGE, "bash", "-lc", cmd],
        stdout=lf, stderr=subprocess.STDOUT, cwd=str(cwd) if cwd else None, env=env
    )
  File "/usr/lib/python3.13/subprocess.py", line 1039, in __init__
    self._execute_child(args, executable, preexec_fn, close_fds,
    ~~~~~~~~~~~~~~~~~~~^^^^^^^^^^^^^^^^^^^^^^^^^^^^^^^^^^^^^^^^^
                        pass_fds, cwd, env,
                        ^^^^^^^^^^^^^^^^^^^
    ...<5 lines>...
                        gid, gids, uid, umask,
                        ^^^^^^^^^^^^^^^^^^^^^^
                        start_new_session, process_group)
                        ^^^^^^^^^^^^^^^^^^^^^^^^^^^^^^^^^
  File "/usr/lib/python3.13/subprocess.py", line 1969, in _execute_child
    raise child_exception_type(errno_num, err_msg, err_filename)
FileNotFoundError: [Errno 2] No such file or directory: 'docker'
INFO:     127.0.0.1:41958 - "GET /tasks/1d24dce5-listener HTTP/1.1" 200 OK
INFO:     127.0.0.1:41958 - "GET /tasks/1d24dce5-listener HTTP/1.1" 200 OK
INFO:     127.0.0.1:41958 - "GET /tasks/1d24dce5-listener HTTP/1.1" 200 OK
INFO:     127.0.0.1:45582 - "GET /tasks/1d24dce5-listener HTTP/1.1" 200 OK
INFO:     127.0.0.1:42462 - "GET /tasks/1d24dce5-listener HTTP/1.1" 200 OK
INFO:     127.0.0.1:44688 - "GET /tasks/1d24dce5-listener HTTP/1.1" 200 OK
INFO:     127.0.0.1:34350 - "GET /tasks/1d24dce5-listener HTTP/1.1" 200 OK
WARNING:  WatchFiles detected changes in 'app.py'. Reloading...
INFO:     Shutting down
INFO:     Waiting for application shutdown.
INFO:     Application shutdown complete.
INFO:     Finished server process [17791]
INFO:     Started server process [18921]
INFO:     Waiting for application startup.
INFO:     Application startup complete.
WARNING:  WatchFiles detected changes in 'app.py'. Reloading...
INFO:     Shutting down
INFO:     Waiting for application shutdown.
INFO:     Application shutdown complete.
INFO:     Finished server process [18921]
INFO:     Started server process [19095]
INFO:     Waiting for application startup.
INFO:     Application startup complete.
ENV-CHECK: java:✔, aapt:✔, aapt2:✔, zipalign:✔, apksigner:✔, apktool:✔
INFO:     127.0.0.1:57956 - "GET /tasks/1d24dce5-listener HTTP/1.1" 404 Not Found
INFO:     127.0.0.1:41222 - "POST /tasks HTTP/1.1" 200 OK
Exception in thread Thread-2 (runner):
Traceback (most recent call last):
  File "/usr/lib/python3.13/threading.py", line 1041, in _bootstrap_inner
    self.run()
    ~~~~~~~~^^
  File "/usr/lib/python3.13/threading.py", line 992, in run
    self._target(*self._args, **self._kwargs)
    ~~~~~~~~~~~~^^^^^^^^^^^^^^^^^^^^^^^^^^^^^
  File "/workspace/orchestrator/app.py", line 2025, in runner
    run_listener_task(t.id, base, t.params)
    ~~~~~~~~~~~~~~~~~^^^^^^^^^^^^^^^^^^^^^^
  File "/workspace/orchestrator/app.py", line 1663, in run_listener_task
    rc = _spawn(cmd, run_log) if not USE_DOCKER else _spawn_container_sh("msfconsole -qx 'resource output/handler.rc; sleep 2; jobs; exit -y'", run_log, base)
                                                     ~~~~~~~~~~~~~~~~~~~^^^^^^^^^^^^^^^^^^^^^^^^^^^^^^^^^^^^^^^^^^^^^^^^^^^^^^^^^^^^^^^^^^^^^^^^^^^^^^^^^^^^^^
  File "/workspace/orchestrator/app.py", line 1542, in _spawn_container_sh
    proc = subprocess.Popen(
        ["docker", "run", "--rm", "-v", f"{task_home}:/workspace", "-v", f"{log_path.parent}:/logs", DOCKER_IMAGE, "bash", "-lc", cmd],
        stdout=lf, stderr=subprocess.STDOUT, cwd=str(cwd) if cwd else None, env=env
    )
  File "/usr/lib/python3.13/subprocess.py", line 1039, in __init__
    self._execute_child(args, executable, preexec_fn, close_fds,
    ~~~~~~~~~~~~~~~~~~~^^^^^^^^^^^^^^^^^^^^^^^^^^^^^^^^^^^^^^^^^
                        pass_fds, cwd, env,
                        ^^^^^^^^^^^^^^^^^^^
    ...<5 lines>...
                        gid, gids, uid, umask,
                        ^^^^^^^^^^^^^^^^^^^^^^
                        start_new_session, process_group)
                        ^^^^^^^^^^^^^^^^^^^^^^^^^^^^^^^^^
  File "/usr/lib/python3.13/subprocess.py", line 1969, in _execute_child
    raise child_exception_type(errno_num, err_msg, err_filename)
FileNotFoundError: [Errno 2] No such file or directory: 'docker'
INFO:     127.0.0.1:45520 - "GET /tasks/6cea5a49-listener HTTP/1.1" 200 OK
INFO:     127.0.0.1:45520 - "GET /tasks/6cea5a49-listener HTTP/1.1" 200 OK
INFO:     127.0.0.1:45520 - "GET /tasks/6cea5a49-listener HTTP/1.1" 200 OK
INFO:     127.0.0.1:41914 - "GET /tasks/6cea5a49-listener HTTP/1.1" 200 OK
INFO:     127.0.0.1:38584 - "GET /tasks/6cea5a49-listener HTTP/1.1" 200 OK
INFO:     127.0.0.1:51368 - "GET /tasks/6cea5a49-listener HTTP/1.1" 200 OK
INFO:     127.0.0.1:35450 - "GET /tasks/6cea5a49-listener HTTP/1.1" 200 OK
INFO:     127.0.0.1:54626 - "GET /tasks/6cea5a49-listener HTTP/1.1" 200 OK
WARNING:  WatchFiles detected changes in 'app.py'. Reloading...
INFO:     Shutting down
INFO:     Waiting for application shutdown.
INFO:     Application shutdown complete.
INFO:     Finished server process [19095]
INFO:     Started server process [20369]
INFO:     Waiting for application startup.
INFO:     Application startup complete.
WARNING:  WatchFiles detected changes in 'app.py'. Reloading...
INFO:     Shutting down
INFO:     Waiting for application shutdown.
INFO:     Application shutdown complete.
INFO:     Finished server process [20369]
INFO:     Started server process [20392]
INFO:     Waiting for application startup.
INFO:     Application startup complete.
WARNING:  WatchFiles detected changes in 'app.py'. Reloading...
INFO:     Shutting down
INFO:     Waiting for application shutdown.
INFO:     Application shutdown complete.
INFO:     Finished server process [20392]
INFO:     Started server process [20415]
INFO:     Waiting for application startup.
INFO:     Application startup complete.
WARNING:  WatchFiles detected changes in 'app.py'. Reloading...
INFO:     Shutting down
INFO:     Waiting for application shutdown.
INFO:     Application shutdown complete.
INFO:     Finished server process [20415]
INFO:     Started server process [20642]
INFO:     Waiting for application startup.
INFO:     Application startup complete.
ENV-CHECK: java:✔, aapt:✔, aapt2:✔, zipalign:✔, apksigner:✔, apktool:✔
INFO:     127.0.0.1:33184 - "GET /tasks/6cea5a49-listener HTTP/1.1" 404 Not Found
WARNING:  WatchFiles detected changes in 'app.py'. Reloading...
INFO:     Shutting down
INFO:     Waiting for application shutdown.
INFO:     Application shutdown complete.
INFO:     Finished server process [20642]
INFO:     Started server process [21776]
INFO:     Waiting for application startup.
INFO:     Application startup complete.
WARNING:  WatchFiles detected changes in 'app.py'. Reloading...
INFO:     Shutting down
INFO:     Waiting for application shutdown.
INFO:     Application shutdown complete.
INFO:     Finished server process [21776]
INFO:     Started server process [21950]
INFO:     Waiting for application startup.
INFO:     Application startup complete.
ENV-CHECK: java:✔, aapt:✔, aapt2:✔, zipalign:✔, apksigner:✔, apktool:✔
INFO:     127.0.0.1:37836 - "POST /tasks HTTP/1.1" 200 OK
Exception in thread Thread-2 (runner):
Traceback (most recent call last):
  File "/usr/lib/python3.13/threading.py", line 1041, in _bootstrap_inner
    self.run()
    ~~~~~~~~^^
  File "/usr/lib/python3.13/threading.py", line 992, in run
    self._target(*self._args, **self._kwargs)
    ~~~~~~~~~~~~^^^^^^^^^^^^^^^^^^^^^^^^^^^^^
  File "/workspace/orchestrator/app.py", line 2067, in runner
    run_listener_task(t.id, base, t.params)
    ~~~~~~~~~~~~~~~~~^^^^^^^^^^^^^^^^^^^^^^
  File "/workspace/orchestrator/app.py", line 1705, in run_listener_task
    rc = _spawn(cmd, run_log) if not USE_DOCKER else _spawn_container_sh("msfconsole -qx 'resource output/handler.rc; sleep 2; jobs; exit -y'", run_log, base)
                                                     ~~~~~~~~~~~~~~~~~~~^^^^^^^^^^^^^^^^^^^^^^^^^^^^^^^^^^^^^^^^^^^^^^^^^^^^^^^^^^^^^^^^^^^^^^^^^^^^^^^^^^^^^^
  File "/workspace/orchestrator/app.py", line 1544, in _spawn_container_sh
    proc = subprocess.Popen(
        ["docker", "run", "--rm", "-v", f"{task_home}:/workspace", "-v", f"{log_path.parent}:/logs", DOCKER_IMAGE, "bash", "-lc", wrapped_cmd],
        stdout=lf, stderr=subprocess.STDOUT, cwd=str(cwd) if cwd else None, env=env
    )
  File "/usr/lib/python3.13/subprocess.py", line 1039, in __init__
    self._execute_child(args, executable, preexec_fn, close_fds,
    ~~~~~~~~~~~~~~~~~~~^^^^^^^^^^^^^^^^^^^^^^^^^^^^^^^^^^^^^^^^^
                        pass_fds, cwd, env,
                        ^^^^^^^^^^^^^^^^^^^
    ...<5 lines>...
                        gid, gids, uid, umask,
                        ^^^^^^^^^^^^^^^^^^^^^^
                        start_new_session, process_group)
                        ^^^^^^^^^^^^^^^^^^^^^^^^^^^^^^^^^
  File "/usr/lib/python3.13/subprocess.py", line 1969, in _execute_child
    raise child_exception_type(errno_num, err_msg, err_filename)
FileNotFoundError: [Errno 2] No such file or directory: 'docker'
INFO:     127.0.0.1:37840 - "GET /tasks/f60cf12f-listener HTTP/1.1" 200 OK
INFO:     127.0.0.1:37840 - "GET /tasks/f60cf12f-listener HTTP/1.1" 200 OK
INFO:     127.0.0.1:37840 - "GET /tasks/f60cf12f-listener HTTP/1.1" 200 OK
INFO:     127.0.0.1:44772 - "GET /tasks/f60cf12f-listener HTTP/1.1" 200 OK
INFO:     127.0.0.1:55410 - "GET /tasks/f60cf12f-listener HTTP/1.1" 200 OK
INFO:     127.0.0.1:52150 - "GET /health HTTP/1.1" 200 OK
INFO:     127.0.0.1:46848 - "GET /tasks/f60cf12f-listener HTTP/1.1" 200 OK
INFO:     127.0.0.1:55392 - "GET /tasks/f60cf12f-listener HTTP/1.1" 200 OK
INFO:     127.0.0.1:53958 - "GET /tasks/f60cf12f-listener HTTP/1.1" 200 OK
WARNING:  WatchFiles detected changes in 'app.py'. Reloading...
INFO:     Shutting down
INFO:     Waiting for application shutdown.
INFO:     Application shutdown complete.
INFO:     Finished server process [21950]
INFO:     Started server process [24010]
INFO:     Waiting for application startup.
INFO:     Application startup complete.
WARNING:  WatchFiles detected changes in 'start_system.py'. Reloading...
INFO:     Shutting down
INFO:     Waiting for application shutdown.
INFO:     Application shutdown complete.
INFO:     Finished server process [24010]
INFO:     Started server process [24033]
INFO:     Waiting for application startup.
INFO:     Application startup complete.
ENV-CHECK: java:✔, aapt:✔, aapt2:✔, zipalign:✔, apksigner:✔, apktool:✔
INFO:     127.0.0.1:45772 - "GET /tasks/f60cf12f-listener HTTP/1.1" 404 Not Found
WARNING:  WatchFiles detected changes in 'app.py'. Reloading...
INFO:     Shutting down
INFO:     Waiting for application shutdown.
INFO:     Application shutdown complete.
INFO:     Finished server process [24033]
INFO:     Started server process [28185]
INFO:     Waiting for application startup.
INFO:     Application startup complete.
WARNING:  WatchFiles detected changes in 'app.py'. Reloading...
INFO:     Shutting down
INFO:     Waiting for application shutdown.
INFO:     Application shutdown complete.
INFO:     Finished server process [28185]
INFO:     Started server process [28619]
INFO:     Waiting for application startup.
INFO:     Application startup complete.
ENV-CHECK: java:✔, aapt:✔, aapt2:✔, zipalign:✔, apksigner:✔, apktool:✔
INFO:     127.0.0.1:56048 - "POST /tasks HTTP/1.1" 200 OK
Exception in thread Thread-2 (runner):
Traceback (most recent call last):
  File "/usr/lib/python3.13/threading.py", line 1041, in _bootstrap_inner
    self.run()
    ~~~~~~~~^^
  File "/usr/lib/python3.13/threading.py", line 992, in run
    self._target(*self._args, **self._kwargs)
    ~~~~~~~~~~~~^^^^^^^^^^^^^^^^^^^^^^^^^^^^^
  File "/workspace/orchestrator/app.py", line 2105, in runner
    run_listener_task(t.id, base, t.params)
    ~~~~~~~~~~~~~~~~~^^^^^^^^^^^^^^^^^^^^^^
  File "/workspace/orchestrator/app.py", line 1741, in run_listener_task
    if _try_rpc_then_finalize():
       ~~~~~~~~~~~~~~~~~~~~~~^^
  File "/workspace/orchestrator/app.py", line 1704, in _try_rpc_then_finalize
    if _msfrpc_env_available():
       ^^^^^^^^^^^^^^^^^^^^^
NameError: name '_msfrpc_env_available' is not defined
INFO:     127.0.0.1:56054 - "GET /tasks/c4143bdb-listener HTTP/1.1" 200 OK
INFO:     127.0.0.1:56054 - "GET /tasks/c4143bdb-listener HTTP/1.1" 200 OK
INFO:     127.0.0.1:56054 - "GET /tasks/c4143bdb-listener HTTP/1.1" 200 OK
INFO:     127.0.0.1:32832 - "GET /tasks/c4143bdb-listener HTTP/1.1" 200 OK
INFO:     127.0.0.1:43162 - "GET /tasks/c4143bdb-listener HTTP/1.1" 200 OK
INFO:     127.0.0.1:42440 - "GET /tasks/c4143bdb-listener HTTP/1.1" 200 OK
WARNING:  WatchFiles detected changes in 'app.py'. Reloading...
INFO:     Shutting down
INFO:     Waiting for application shutdown.
INFO:     Application shutdown complete.
INFO:     Finished server process [28619]
INFO:     Started server process [30363]
INFO:     Waiting for application startup.
INFO:     Application startup complete.
ENV-CHECK: java:✔, aapt:✔, aapt2:✔, zipalign:✔, apksigner:✔, apktool:✔
INFO:     127.0.0.1:34040 - "GET /tasks/c4143bdb-listener HTTP/1.1" 404 Not Found
WARNING:  WatchFiles detected changes in 'app.py'. Reloading...
INFO:     Shutting down
INFO:     Waiting for application shutdown.
INFO:     Application shutdown complete.
INFO:     Finished server process [30363]
INFO:     Started server process [30570]
INFO:     Waiting for application startup.
INFO:     Application startup complete.
ENV-CHECK: java:✔, aapt:✔, aapt2:✔, zipalign:✔, apksigner:✔, apktool:✔
INFO:     127.0.0.1:57200 - "POST /tasks HTTP/1.1" 200 OK
Exception in thread Thread-2 (runner):
Traceback (most recent call last):
  File "/usr/lib/python3.13/threading.py", line 1041, in _bootstrap_inner
    self.run()
    ~~~~~~~~^^
  File "/usr/lib/python3.13/threading.py", line 992, in run
    self._target(*self._args, **self._kwargs)
    ~~~~~~~~~~~~^^^^^^^^^^^^^^^^^^^^^^^^^^^^^
  File "/workspace/orchestrator/app.py", line 2119, in runner
    run_listener_task(t.id, base, t.params)
    ~~~~~~~~~~~~~~~~~^^^^^^^^^^^^^^^^^^^^^^
  File "/workspace/orchestrator/app.py", line 1725, in run_listener_task
    if _try_rpc_then_finalize():
       ~~~~~~~~~~~~~~~~~~~~~~^^
  File "/workspace/orchestrator/app.py", line 1710, in _try_rpc_then_finalize
    if _msfrpc_env_available():
       ^^^^^^^^^^^^^^^^^^^^^
NameError: name '_msfrpc_env_available' is not defined
INFO:     127.0.0.1:57212 - "GET /tasks/d4856db8-listener HTTP/1.1" 200 OK
INFO:     127.0.0.1:57212 - "GET /tasks/d4856db8-listener HTTP/1.1" 200 OK
WARNING:  WatchFiles detected changes in 'app.py'. Reloading...
INFO:     Shutting down
INFO:     Waiting for application shutdown.
INFO:     Application shutdown complete.
INFO:     Finished server process [30570]
INFO:     Started server process [30648]
INFO:     Waiting for application startup.
INFO:     Application startup complete.
ENV-CHECK: java:✔, aapt:✔, aapt2:✔, zipalign:✔, apksigner:✔, apktool:✔
INFO:     127.0.0.1:57222 - "GET /tasks/d4856db8-listener HTTP/1.1" 404 Not Found
WARNING:  WatchFiles detected changes in 'app.py'. Reloading...
INFO:     Shutting down
INFO:     Waiting for application shutdown.
INFO:     Application shutdown complete.
INFO:     Finished server process [30648]
INFO:     Started server process [30672]
INFO:     Waiting for application startup.
INFO:     Application startup complete.
WARNING:  WatchFiles detected changes in 'app.py'. Reloading...
INFO:     Shutting down
INFO:     Waiting for application shutdown.
INFO:     Application shutdown complete.
INFO:     Finished server process [30672]
INFO:     Started server process [30695]
INFO:     Waiting for application startup.
INFO:     Application startup complete.
WARNING:  WatchFiles detected changes in 'app.py'. Reloading...
INFO:     Shutting down
INFO:     Waiting for application shutdown.
INFO:     Application shutdown complete.
INFO:     Finished server process [30695]
INFO:     Started server process [31311]
INFO:     Waiting for application startup.
INFO:     Application startup complete.
ENV-CHECK: java:✔, aapt:✔, aapt2:✔, zipalign:✔, apksigner:✔, apktool:✔
INFO:     127.0.0.1:38324 - "POST /tasks HTTP/1.1" 422 Unprocessable Content
INFO:     127.0.0.1:60350 - "POST /tasks HTTP/1.1" 200 OK
Exception in thread Thread-2 (runner):
Traceback (most recent call last):
  File "/usr/lib/python3.13/threading.py", line 1041, in _bootstrap_inner
    self.run()
    ~~~~~~~~^^
  File "/usr/lib/python3.13/threading.py", line 992, in run
    self._target(*self._args, **self._kwargs)
    ~~~~~~~~~~~~^^^^^^^^^^^^^^^^^^^^^^^^^^^^^
  File "/workspace/orchestrator/app.py", line 2161, in runner
    run_listener_task(t.id, base, t.params)
    ~~~~~~~~~~~~~~~~~^^^^^^^^^^^^^^^^^^^^^^
  File "/workspace/orchestrator/app.py", line 1775, in run_listener_task
    _finalize_task(t, base, succeeded=True, err=None)
    ~~~~~~~~~~~~~~^^^^^^^^^^^^^^^^^^^^^^^^^^^^^^^^^^^
  File "/workspace/orchestrator/app.py", line 1619, in _finalize_task
    if DB_ENABLED and DB:
       ^^^^^^^^^^
NameError: name 'DB_ENABLED' is not defined
INFO:     127.0.0.1:60352 - "GET /tasks/56512bfb-listener HTTP/1.1" 200 OK
INFO:     127.0.0.1:60352 - "GET /tasks/56512bfb-listener/artifacts HTTP/1.1" 200 OK
INFO:     127.0.0.1:60352 - "GET /tasks/56512bfb-listener/artifacts/handler.rc/download HTTP/1.1" 200 OK
INFO:     127.0.0.1:33112 - "POST /tasks HTTP/1.1" 200 OK
Exception in thread Thread-3 (runner):
Traceback (most recent call last):
  File "/usr/lib/python3.13/threading.py", line 1041, in _bootstrap_inner
    self.run()
    ~~~~~~~~^^
  File "/usr/lib/python3.13/threading.py", line 992, in run
    self._target(*self._args, **self._kwargs)
    ~~~~~~~~~~~~^^^^^^^^^^^^^^^^^^^^^^^^^^^^^
  File "/workspace/orchestrator/app.py", line 2161, in runner
    run_listener_task(t.id, base, t.params)
    ~~~~~~~~~~~~~~~~~^^^^^^^^^^^^^^^^^^^^^^
  File "/workspace/orchestrator/app.py", line 1775, in run_listener_task
    _finalize_task(t, base, succeeded=True, err=None)
    ~~~~~~~~~~~~~~^^^^^^^^^^^^^^^^^^^^^^^^^^^^^^^^^^^
  File "/workspace/orchestrator/app.py", line 1619, in _finalize_task
    if DB_ENABLED and DB:
       ^^^^^^^^^^
NameError: name 'DB_ENABLED' is not defined
INFO:     127.0.0.1:33118 - "GET /tasks/36d4e20a-listener HTTP/1.1" 200 OK
INFO:     127.0.0.1:33118 - "GET /tasks/36d4e20a-listener/artifacts HTTP/1.1" 200 OK
INFO:     127.0.0.1:33118 - "GET /tasks/36d4e20a-listener/artifacts/handler.rc/download HTTP/1.1" 200 OK
INFO:     127.0.0.1:56488 - "POST /tasks HTTP/1.1" 200 OK
Exception in thread Thread-4 (runner):
Traceback (most recent call last):
  File "/usr/lib/python3.13/threading.py", line 1041, in _bootstrap_inner
    self.run()
    ~~~~~~~~^^
  File "/usr/lib/python3.13/threading.py", line 992, in run
    self._target(*self._args, **self._kwargs)
    ~~~~~~~~~~~~^^^^^^^^^^^^^^^^^^^^^^^^^^^^^
  File "/workspace/orchestrator/app.py", line 2161, in runner
    run_listener_task(t.id, base, t.params)
    ~~~~~~~~~~~~~~~~~^^^^^^^^^^^^^^^^^^^^^^
  File "/workspace/orchestrator/app.py", line 1775, in run_listener_task
    _finalize_task(t, base, succeeded=True, err=None)
    ~~~~~~~~~~~~~~^^^^^^^^^^^^^^^^^^^^^^^^^^^^^^^^^^^
  File "/workspace/orchestrator/app.py", line 1619, in _finalize_task
    if DB_ENABLED and DB:
       ^^^^^^^^^^
NameError: name 'DB_ENABLED' is not defined
INFO:     127.0.0.1:56494 - "GET /tasks/3b6c4992-listener HTTP/1.1" 200 OK
INFO:     127.0.0.1:56494 - "GET /tasks/3b6c4992-listener/artifacts HTTP/1.1" 200 OK
INFO:     127.0.0.1:56494 - "GET /tasks/3b6c4992-listener/artifacts/handler.rc/download HTTP/1.1" 200 OK
INFO:     127.0.0.1:37220 - "POST /tasks HTTP/1.1" 200 OK
Exception in thread Thread-5 (runner):
Traceback (most recent call last):
  File "/usr/lib/python3.13/threading.py", line 1041, in _bootstrap_inner
    self.run()
    ~~~~~~~~^^
  File "/usr/lib/python3.13/threading.py", line 992, in run
    self._target(*self._args, **self._kwargs)
    ~~~~~~~~~~~~^^^^^^^^^^^^^^^^^^^^^^^^^^^^^
  File "/workspace/orchestrator/app.py", line 2161, in runner
    run_listener_task(t.id, base, t.params)
    ~~~~~~~~~~~~~~~~~^^^^^^^^^^^^^^^^^^^^^^
  File "/workspace/orchestrator/app.py", line 1775, in run_listener_task
    _finalize_task(t, base, succeeded=True, err=None)
    ~~~~~~~~~~~~~~^^^^^^^^^^^^^^^^^^^^^^^^^^^^^^^^^^^
  File "/workspace/orchestrator/app.py", line 1619, in _finalize_task
    if DB_ENABLED and DB:
       ^^^^^^^^^^
NameError: name 'DB_ENABLED' is not defined
INFO:     127.0.0.1:37232 - "GET /tasks/7926d16a-listener HTTP/1.1" 200 OK
INFO:     127.0.0.1:37232 - "GET /tasks/7926d16a-listener/artifacts HTTP/1.1" 200 OK
INFO:     127.0.0.1:37232 - "GET /tasks/7926d16a-listener/artifacts/handler.rc/download HTTP/1.1" 200 OK
WARNING:  WatchFiles detected changes in 'app.py'. Reloading...
INFO:     Shutting down
INFO:     Waiting for application shutdown.
INFO:     Application shutdown complete.
INFO:     Finished server process [31311]
INFO:     Started server process [36596]
INFO:     Waiting for application startup.
INFO:     Application startup complete.
ENV-CHECK: java:✔, aapt:✔, aapt2:✔, zipalign:✔, apksigner:✔, apktool:✔
INFO:     127.0.0.1:36198 - "POST /tasks HTTP/1.1" 200 OK
INFO:     127.0.0.1:36214 - "GET /tasks/e0d7a0d6-listener HTTP/1.1" 200 OK
INFO:     127.0.0.1:36214 - "GET /tasks/e0d7a0d6-listener/artifacts HTTP/1.1" 200 OK
INFO:     127.0.0.1:36214 - "GET /tasks/e0d7a0d6-listener/artifacts/handler.rc/download HTTP/1.1" 200 OK
INFO:     127.0.0.1:54308 - "POST /tasks HTTP/1.1" 500 Internal Server Error
ERROR:    Exception in ASGI application
Traceback (most recent call last):
  File "/home/ubuntu/.local/lib/python3.13/site-packages/uvicorn/protocols/http/httptools_impl.py", line 401, in run_asgi
    result = await app(  # type: ignore[func-returns-value]
             ^^^^^^^^^^^^^^^^^^^^^^^^^^^^^^^^^^^^^^^^^^^^^^
        self.scope, self.receive, self.send
        ^^^^^^^^^^^^^^^^^^^^^^^^^^^^^^^^^^^
    )
    ^
  File "/home/ubuntu/.local/lib/python3.13/site-packages/uvicorn/middleware/proxy_headers.py", line 70, in __call__
    return await self.app(scope, receive, send)
           ^^^^^^^^^^^^^^^^^^^^^^^^^^^^^^^^^^^^
  File "/home/ubuntu/.local/lib/python3.13/site-packages/fastapi/applications.py", line 1054, in __call__
    await super().__call__(scope, receive, send)
  File "/home/ubuntu/.local/lib/python3.13/site-packages/starlette/applications.py", line 113, in __call__
    await self.middleware_stack(scope, receive, send)
  File "/home/ubuntu/.local/lib/python3.13/site-packages/starlette/middleware/errors.py", line 187, in __call__
    raise exc
  File "/home/ubuntu/.local/lib/python3.13/site-packages/starlette/middleware/errors.py", line 165, in __call__
    await self.app(scope, receive, _send)
  File "/home/ubuntu/.local/lib/python3.13/site-packages/starlette/middleware/exceptions.py", line 62, in __call__
    await wrap_app_handling_exceptions(self.app, conn)(scope, receive, send)
  File "/home/ubuntu/.local/lib/python3.13/site-packages/starlette/_exception_handler.py", line 62, in wrapped_app
    raise exc
  File "/home/ubuntu/.local/lib/python3.13/site-packages/starlette/_exception_handler.py", line 51, in wrapped_app
    await app(scope, receive, sender)
  File "/home/ubuntu/.local/lib/python3.13/site-packages/starlette/routing.py", line 715, in __call__
    await self.middleware_stack(scope, receive, send)
  File "/home/ubuntu/.local/lib/python3.13/site-packages/starlette/routing.py", line 735, in app
    await route.handle(scope, receive, send)
  File "/home/ubuntu/.local/lib/python3.13/site-packages/starlette/routing.py", line 288, in handle
    await self.app(scope, receive, send)
  File "/home/ubuntu/.local/lib/python3.13/site-packages/starlette/routing.py", line 76, in app
    await wrap_app_handling_exceptions(app, request)(scope, receive, send)
  File "/home/ubuntu/.local/lib/python3.13/site-packages/starlette/_exception_handler.py", line 62, in wrapped_app
    raise exc
  File "/home/ubuntu/.local/lib/python3.13/site-packages/starlette/_exception_handler.py", line 51, in wrapped_app
    await app(scope, receive, sender)
  File "/home/ubuntu/.local/lib/python3.13/site-packages/starlette/routing.py", line 73, in app
    response = await f(request)
               ^^^^^^^^^^^^^^^^
  File "/home/ubuntu/.local/lib/python3.13/site-packages/fastapi/routing.py", line 301, in app
    raw_response = await run_endpoint_function(
                   ^^^^^^^^^^^^^^^^^^^^^^^^^^^^
    ...<3 lines>...
    )
    ^
  File "/home/ubuntu/.local/lib/python3.13/site-packages/fastapi/routing.py", line 214, in run_endpoint_function
    return await run_in_threadpool(dependant.call, **values)
           ^^^^^^^^^^^^^^^^^^^^^^^^^^^^^^^^^^^^^^^^^^^^^^^^^
  File "/home/ubuntu/.local/lib/python3.13/site-packages/starlette/concurrency.py", line 39, in run_in_threadpool
    return await anyio.to_thread.run_sync(func, *args)
           ^^^^^^^^^^^^^^^^^^^^^^^^^^^^^^^^^^^^^^^^^^^
  File "/home/ubuntu/.local/lib/python3.13/site-packages/anyio/to_thread.py", line 56, in run_sync
    return await get_async_backend().run_sync_in_worker_thread(
           ^^^^^^^^^^^^^^^^^^^^^^^^^^^^^^^^^^^^^^^^^^^^^^^^^^^^
        func, args, abandon_on_cancel=abandon_on_cancel, limiter=limiter
        ^^^^^^^^^^^^^^^^^^^^^^^^^^^^^^^^^^^^^^^^^^^^^^^^^^^^^^^^^^^^^^^^
    )
    ^
  File "/home/ubuntu/.local/lib/python3.13/site-packages/anyio/_backends/_asyncio.py", line 2476, in run_sync_in_worker_thread
    return await future
           ^^^^^^^^^^^^
  File "/home/ubuntu/.local/lib/python3.13/site-packages/anyio/_backends/_asyncio.py", line 967, in run
    result = context.run(func, *args)
  File "/workspace/orchestrator/app.py", line 2133, in create_task
    t, base = _prepare_task(req.kind, req.params)
              ~~~~~~~~~~~~~^^^^^^^^^^^^^^^^^^^^^^
  File "/workspace/orchestrator/app.py", line 1589, in _prepare_task
    t = Task(id=task_id, date=date, kind=kind, state=TaskStatus.SUBMITTED, created_at=time.time(), params=params, logs={})
  File "/home/ubuntu/.local/lib/python3.13/site-packages/pydantic/main.py", line 193, in __init__
    self.__pydantic_validator__.validate_python(data, self_instance=self)
    ~~~~~~~~~~~~~~~~~~~~~~~~~~~~~~~~~~~~~~~~~~~^^^^^^^^^^^^^^^^^^^^^^^^^^
pydantic_core._pydantic_core.ValidationError: 1 validation error for Task
params.file_info
  Input should be a valid string [type=string_type, input_value={'file_id': '9fb982ca', '... 'file_size': 8135671}}}, input_type=dict]
    For further information visit https://errors.pydantic.dev/2.8/v/string_type
WARNING:  WatchFiles detected changes in 'app.py'. Reloading...
INFO:     Shutting down
INFO:     Waiting for application shutdown.
INFO:     Application shutdown complete.
INFO:     Finished server process [36596]
INFO:     Started server process [37710]
INFO:     Waiting for application startup.
INFO:     Application startup complete.
WARNING:  WatchFiles detected changes in 'app.py'. Reloading...
INFO:     Shutting down
INFO:     Waiting for application shutdown.
INFO:     Application shutdown complete.
INFO:     Finished server process [37710]
INFO:     Started server process [37986]
INFO:     Waiting for application startup.
INFO:     Application startup complete.
ENV-CHECK: java:✔, aapt:✔, aapt2:✔, zipalign:✔, apksigner:✔, apktool:✔
INFO:     127.0.0.1:40412 - "POST /tasks HTTP/1.1" 200 OK
INFO:     127.0.0.1:40418 - "GET /tasks/20b7c333-listener HTTP/1.1" 200 OK
INFO:     127.0.0.1:40418 - "GET /tasks/20b7c333-listener/artifacts HTTP/1.1" 200 OK
INFO:     127.0.0.1:40418 - "GET /tasks/20b7c333-listener/artifacts/handler.rc/download HTTP/1.1" 200 OK
INFO:     127.0.0.1:34448 - "POST /tasks HTTP/1.1" 200 OK
Exception in thread Thread-3 (runner):
Traceback (most recent call last):
  File "/usr/lib/python3.13/threading.py", line 1041, in _bootstrap_inner
    self.run()
    ~~~~~~~~^^
  File "/usr/lib/python3.13/threading.py", line 992, in run
    self._target(*self._args, **self._kwargs)
    ~~~~~~~~~~~~^^^^^^^^^^^^^^^^^^^^^^^^^^^^^
  File "/workspace/orchestrator/app.py", line 2177, in runner
    asyncio.run(run_upload_apk_task(t.id, base, t.params))
    ~~~~~~~~~~~^^^^^^^^^^^^^^^^^^^^^^^^^^^^^^^^^^^^^^^^^^^
  File "/usr/lib/python3.13/asyncio/runners.py", line 195, in run
    return runner.run(main)
           ~~~~~~~~~~^^^^^^
  File "/usr/lib/python3.13/asyncio/runners.py", line 118, in run
    return self._loop.run_until_complete(task)
           ~~~~~~~~~~~~~~~~~~~~~~~~~~~~~^^^^^^
  File "uvloop/loop.pyx", line 1518, in uvloop.loop.Loop.run_until_complete
  File "/workspace/orchestrator/app.py", line 718, in run_upload_apk_task
    c2_config = C2Config(
        server_host="192.168.1.100",
    ...<5 lines>...
        heartbeat_interval=60
    )
TypeError: C2Config.__init__() got an unexpected keyword argument 'encryption_enabled'
INFO:     127.0.0.1:34454 - "GET /tasks/948973f7-upload_apk HTTP/1.1" 200 OK
INFO:     127.0.0.1:34454 - "GET /tasks/948973f7-upload_apk HTTP/1.1" 200 OK
INFO:     127.0.0.1:34454 - "GET /tasks/948973f7-upload_apk HTTP/1.1" 200 OK
INFO:     127.0.0.1:43412 - "GET /tasks/948973f7-upload_apk HTTP/1.1" 200 OK
INFO:     127.0.0.1:45204 - "GET /tasks/948973f7-upload_apk HTTP/1.1" 200 OK
INFO:     127.0.0.1:43642 - "GET /tasks/948973f7-upload_apk HTTP/1.1" 200 OK
INFO:     127.0.0.1:53274 - "GET /tasks/948973f7-upload_apk HTTP/1.1" 200 OK
INFO:     127.0.0.1:45896 - "GET /tasks/948973f7-upload_apk HTTP/1.1" 200 OK
INFO:     127.0.0.1:57698 - "GET /tasks/948973f7-upload_apk HTTP/1.1" 200 OK
INFO:     127.0.0.1:55864 - "GET /tasks/948973f7-upload_apk/artifacts HTTP/1.1" 200 OK
WARNING:  WatchFiles detected changes in 'app.py'. Reloading...
INFO:     Shutting down
INFO:     Waiting for application shutdown.
INFO:     Application shutdown complete.
INFO:     Finished server process [37986]
INFO:     Started server process [39866]
INFO:     Waiting for application startup.
INFO:     Application startup complete.
ENV-CHECK: java:✔, aapt:✔, aapt2:✔, zipalign:✔, apksigner:✔, apktool:✔
INFO:     127.0.0.1:59894 - "GET /tasks/948973f7-upload_apk HTTP/1.1" 404 Not Found
INFO:     127.0.0.1:60778 - "POST /tasks HTTP/1.1" 200 OK
INFO:     127.0.0.1:60788 - "GET /tasks/cd854059-listener HTTP/1.1" 200 OK
INFO:     127.0.0.1:60788 - "GET /tasks/cd854059-listener/artifacts HTTP/1.1" 200 OK
INFO:     127.0.0.1:60788 - "GET /tasks/cd854059-listener/artifacts/handler.rc/download HTTP/1.1" 200 OK
Exception in thread Thread-3 (runner):
INFO:     127.0.0.1:43004 - "POST /tasks HTTP/1.1" 200 OK
Traceback (most recent call last):
  File "/usr/lib/python3.13/threading.py", line 1041, in _bootstrap_inner
    self.run()
    ~~~~~~~~^^
  File "/usr/lib/python3.13/threading.py", line 992, in run
    self._target(*self._args, **self._kwargs)
    ~~~~~~~~~~~~^^^^^^^^^^^^^^^^^^^^^^^^^^^^^
  File "/workspace/orchestrator/app.py", line 2176, in runner
    asyncio.run(run_upload_apk_task(t.id, base, t.params))
    ~~~~~~~~~~~^^^^^^^^^^^^^^^^^^^^^^^^^^^^^^^^^^^^^^^^^^^
  File "/usr/lib/python3.13/asyncio/runners.py", line 195, in run
    return runner.run(main)
           ~~~~~~~~~~^^^^^^
  File "/usr/lib/python3.13/asyncio/runners.py", line 118, in run
    return self._loop.run_until_complete(task)
           ~~~~~~~~~~~~~~~~~~~~~~~~~~~~~^^^^^^
  File "uvloop/loop.pyx", line 1518, in uvloop.loop.Loop.run_until_complete
  File "/workspace/orchestrator/app.py", line 746, in run_upload_apk_task
    performance_config = PerformanceConfig(
        optimization_level=PerformanceLevel.AGGRESSIVE,
    ...<4 lines>...
        enable_monitoring=True
    )
TypeError: PerformanceConfig.__init__() got an unexpected keyword argument 'network_optimization'
INFO:     127.0.0.1:43006 - "GET /tasks/1e6f4c8b-upload_apk HTTP/1.1" 200 OK
INFO:     127.0.0.1:43006 - "GET /tasks/1e6f4c8b-upload_apk HTTP/1.1" 200 OK
INFO:     127.0.0.1:43006 - "GET /tasks/1e6f4c8b-upload_apk HTTP/1.1" 200 OK
INFO:     127.0.0.1:52780 - "GET /tasks/1e6f4c8b-upload_apk HTTP/1.1" 200 OK
INFO:     127.0.0.1:39464 - "GET /tasks/1e6f4c8b-upload_apk HTTP/1.1" 200 OK
INFO:     127.0.0.1:41662 - "GET /tasks/948973f7-upload_apk HTTP/1.1" 404 Not Found
INFO:     127.0.0.1:41666 - "GET /tasks/3e4b3d9e-upload_apk HTTP/1.1" 404 Not Found
INFO:     127.0.0.1:41680 - "GET /tasks/1e6f4c8b-upload_apk HTTP/1.1" 200 OK
INFO:     127.0.0.1:38930 - "GET /tasks/1e6f4c8b-upload_apk HTTP/1.1" 200 OK
INFO:     127.0.0.1:46410 - "POST /tasks HTTP/1.1" 200 OK
INFO:     127.0.0.1:46418 - "GET /tasks/06133189-listener HTTP/1.1" 200 OK
INFO:     127.0.0.1:46418 - "GET /tasks/06133189-listener/artifacts HTTP/1.1" 200 OK
INFO:     127.0.0.1:46418 - "GET /tasks/06133189-listener/artifacts/handler.rc/download HTTP/1.1" 200 OK
Exception in thread Thread-5 (runner):
Traceback (most recent call last):
  File "/usr/lib/python3.13/threading.py", line 1041, in _bootstrap_inner
    self.run()
    ~~~~~~~~^^
  File "/usr/lib/python3.13/threading.py", line 992, in run
    self._target(*self._args, **self._kwargs)
    ~~~~~~~~~~~~^^^^^^^^^^^^^^^^^^^^^^^^^^^^^
  File "/workspace/orchestrator/app.py", line 2176, in runner
    asyncio.run(run_upload_apk_task(t.id, base, t.params))
    ~~~~~~~~~~~^^^^^^^^^^^^^^^^^^^^^^^^^^^^^^^^^^^^^^^^^^^
  File "/usr/lib/python3.13/asyncio/runners.py", line 195, in run
    return runner.run(main)
           ~~~~~~~~~~^^^^^^
  File "/usr/lib/python3.13/asyncio/runners.py", line 118, in run
    return self._loop.run_until_complete(task)
           ~~~~~~~~~~~~~~~~~~~~~~~~~~~~~^^^^^^
  File "uvloop/loop.pyx", line 1518, in uvloop.loop.Loop.run_until_complete
  File "/workspace/orchestrator/app.py", line 746, in run_upload_apk_task
    performance_config = PerformanceConfig(
        optimization_level=PerformanceLevel.AGGRESSIVE,
    ...<4 lines>...
        enable_monitoring=True
    )
TypeError: PerformanceConfig.__init__() got an unexpected keyword argument 'network_optimization'
INFO:     127.0.0.1:51892 - "POST /tasks HTTP/1.1" 200 OK
INFO:     127.0.0.1:51902 - "GET /tasks/aa86dd57-upload_apk HTTP/1.1" 200 OK
INFO:     127.0.0.1:51902 - "GET /tasks/aa86dd57-upload_apk HTTP/1.1" 200 OK
INFO:     127.0.0.1:51902 - "GET /tasks/aa86dd57-upload_apk HTTP/1.1" 200 OK
INFO:     127.0.0.1:56982 - "GET /tasks/aa86dd57-upload_apk HTTP/1.1" 200 OK
INFO:     127.0.0.1:48750 - "GET /tasks/1e6f4c8b-upload_apk HTTP/1.1" 200 OK
INFO:     127.0.0.1:48762 - "GET /tasks/aa86dd57-upload_apk HTTP/1.1" 200 OK
INFO:     127.0.0.1:45336 - "GET /tasks/aa86dd57-upload_apk HTTP/1.1" 200 OK
INFO:     127.0.0.1:42988 - "GET /tasks/aa86dd57-upload_apk HTTP/1.1" 200 OK
INFO:     127.0.0.1:34520 - "GET /tasks/aa86dd57-upload_apk HTTP/1.1" 200 OK
INFO:     127.0.0.1:34510 - "GET /tasks/aa86dd57-upload_apk HTTP/1.1" 200 OK
