INFO:     Will watch for changes in these directories: ['/workspace/orchestrator']
INFO:     Uvicorn running on http://127.0.0.1:8000 (Press CTRL+C to quit)
INFO:     Started reloader process [9765] using WatchFiles
INFO:     Started server process [9768]
INFO:     Waiting for application startup.
INFO:     Application startup complete.
ENV-CHECK: java:✔, aapt:✔, aapt2:✔, zipalign:✔, apksigner:✔, apktool:✔
INFO:     127.0.0.1:43722 - "GET /health HTTP/1.1" 200 OK
INFO:     127.0.0.1:50826 - "POST /tasks HTTP/1.1" 422 Unprocessable Content
INFO:     127.0.0.1:35648 - "GET /health HTTP/1.1" 200 OK
INFO:     127.0.0.1:60034 - "POST /tasks HTTP/1.1" 500 Internal Server Error
ERROR:    Exception in ASGI application
Traceback (most recent call last):
  File "/home/ubuntu/.local/lib/python3.13/site-packages/uvicorn/protocols/http/httptools_impl.py", line 401, in run_asgi
    result = await app(  # type: ignore[func-returns-value]
             ^^^^^^^^^^^^^^^^^^^^^^^^^^^^^^^^^^^^^^^^^^^^^^
        self.scope, self.receive, self.send
        ^^^^^^^^^^^^^^^^^^^^^^^^^^^^^^^^^^^
    )
    ^
  File "/home/ubuntu/.local/lib/python3.13/site-packages/uvicorn/middleware/proxy_headers.py", line 70, in __call__
    return await self.app(scope, receive, send)
           ^^^^^^^^^^^^^^^^^^^^^^^^^^^^^^^^^^^^
  File "/home/ubuntu/.local/lib/python3.13/site-packages/fastapi/applications.py", line 1054, in __call__
    await super().__call__(scope, receive, send)
  File "/home/ubuntu/.local/lib/python3.13/site-packages/starlette/applications.py", line 113, in __call__
    await self.middleware_stack(scope, receive, send)
  File "/home/ubuntu/.local/lib/python3.13/site-packages/starlette/middleware/errors.py", line 187, in __call__
    raise exc
  File "/home/ubuntu/.local/lib/python3.13/site-packages/starlette/middleware/errors.py", line 165, in __call__
    await self.app(scope, receive, _send)
  File "/home/ubuntu/.local/lib/python3.13/site-packages/starlette/middleware/exceptions.py", line 62, in __call__
    await wrap_app_handling_exceptions(self.app, conn)(scope, receive, send)
  File "/home/ubuntu/.local/lib/python3.13/site-packages/starlette/_exception_handler.py", line 62, in wrapped_app
    raise exc
  File "/home/ubuntu/.local/lib/python3.13/site-packages/starlette/_exception_handler.py", line 51, in wrapped_app
    await app(scope, receive, sender)
  File "/home/ubuntu/.local/lib/python3.13/site-packages/starlette/routing.py", line 715, in __call__
    await self.middleware_stack(scope, receive, send)
  File "/home/ubuntu/.local/lib/python3.13/site-packages/starlette/routing.py", line 735, in app
    await route.handle(scope, receive, send)
  File "/home/ubuntu/.local/lib/python3.13/site-packages/starlette/routing.py", line 288, in handle
    await self.app(scope, receive, send)
  File "/home/ubuntu/.local/lib/python3.13/site-packages/starlette/routing.py", line 76, in app
    await wrap_app_handling_exceptions(app, request)(scope, receive, send)
  File "/home/ubuntu/.local/lib/python3.13/site-packages/starlette/_exception_handler.py", line 62, in wrapped_app
    raise exc
  File "/home/ubuntu/.local/lib/python3.13/site-packages/starlette/_exception_handler.py", line 51, in wrapped_app
    await app(scope, receive, sender)
  File "/home/ubuntu/.local/lib/python3.13/site-packages/starlette/routing.py", line 73, in app
    response = await f(request)
               ^^^^^^^^^^^^^^^^
  File "/home/ubuntu/.local/lib/python3.13/site-packages/fastapi/routing.py", line 301, in app
    raw_response = await run_endpoint_function(
                   ^^^^^^^^^^^^^^^^^^^^^^^^^^^^
    ...<3 lines>...
    )
    ^
  File "/home/ubuntu/.local/lib/python3.13/site-packages/fastapi/routing.py", line 214, in run_endpoint_function
    return await run_in_threadpool(dependant.call, **values)
           ^^^^^^^^^^^^^^^^^^^^^^^^^^^^^^^^^^^^^^^^^^^^^^^^^
  File "/home/ubuntu/.local/lib/python3.13/site-packages/starlette/concurrency.py", line 39, in run_in_threadpool
    return await anyio.to_thread.run_sync(func, *args)
           ^^^^^^^^^^^^^^^^^^^^^^^^^^^^^^^^^^^^^^^^^^^
  File "/home/ubuntu/.local/lib/python3.13/site-packages/anyio/to_thread.py", line 56, in run_sync
    return await get_async_backend().run_sync_in_worker_thread(
           ^^^^^^^^^^^^^^^^^^^^^^^^^^^^^^^^^^^^^^^^^^^^^^^^^^^^
        func, args, abandon_on_cancel=abandon_on_cancel, limiter=limiter
        ^^^^^^^^^^^^^^^^^^^^^^^^^^^^^^^^^^^^^^^^^^^^^^^^^^^^^^^^^^^^^^^^
    )
    ^
  File "/home/ubuntu/.local/lib/python3.13/site-packages/anyio/_backends/_asyncio.py", line 2476, in run_sync_in_worker_thread
    return await future
           ^^^^^^^^^^^^
  File "/home/ubuntu/.local/lib/python3.13/site-packages/anyio/_backends/_asyncio.py", line 967, in run
    result = context.run(func, *args)
  File "/workspace/orchestrator/app.py", line 1985, in create_task
    if DB_ENABLED and DB:
       ^^^^^^^^^^
NameError: name 'DB_ENABLED' is not defined
INFO:     127.0.0.1:40752 - "POST /tasks HTTP/1.1" 500 Internal Server Error
ERROR:    Exception in ASGI application
Traceback (most recent call last):
  File "/home/ubuntu/.local/lib/python3.13/site-packages/uvicorn/protocols/http/httptools_impl.py", line 401, in run_asgi
    result = await app(  # type: ignore[func-returns-value]
             ^^^^^^^^^^^^^^^^^^^^^^^^^^^^^^^^^^^^^^^^^^^^^^
        self.scope, self.receive, self.send
        ^^^^^^^^^^^^^^^^^^^^^^^^^^^^^^^^^^^
    )
    ^
  File "/home/ubuntu/.local/lib/python3.13/site-packages/uvicorn/middleware/proxy_headers.py", line 70, in __call__
    return await self.app(scope, receive, send)
           ^^^^^^^^^^^^^^^^^^^^^^^^^^^^^^^^^^^^
  File "/home/ubuntu/.local/lib/python3.13/site-packages/fastapi/applications.py", line 1054, in __call__
    await super().__call__(scope, receive, send)
  File "/home/ubuntu/.local/lib/python3.13/site-packages/starlette/applications.py", line 113, in __call__
    await self.middleware_stack(scope, receive, send)
  File "/home/ubuntu/.local/lib/python3.13/site-packages/starlette/middleware/errors.py", line 187, in __call__
    raise exc
  File "/home/ubuntu/.local/lib/python3.13/site-packages/starlette/middleware/errors.py", line 165, in __call__
    await self.app(scope, receive, _send)
  File "/home/ubuntu/.local/lib/python3.13/site-packages/starlette/middleware/exceptions.py", line 62, in __call__
    await wrap_app_handling_exceptions(self.app, conn)(scope, receive, send)
  File "/home/ubuntu/.local/lib/python3.13/site-packages/starlette/_exception_handler.py", line 62, in wrapped_app
    raise exc
  File "/home/ubuntu/.local/lib/python3.13/site-packages/starlette/_exception_handler.py", line 51, in wrapped_app
    await app(scope, receive, sender)
  File "/home/ubuntu/.local/lib/python3.13/site-packages/starlette/routing.py", line 715, in __call__
    await self.middleware_stack(scope, receive, send)
  File "/home/ubuntu/.local/lib/python3.13/site-packages/starlette/routing.py", line 735, in app
    await route.handle(scope, receive, send)
  File "/home/ubuntu/.local/lib/python3.13/site-packages/starlette/routing.py", line 288, in handle
    await self.app(scope, receive, send)
  File "/home/ubuntu/.local/lib/python3.13/site-packages/starlette/routing.py", line 76, in app
    await wrap_app_handling_exceptions(app, request)(scope, receive, send)
  File "/home/ubuntu/.local/lib/python3.13/site-packages/starlette/_exception_handler.py", line 62, in wrapped_app
    raise exc
  File "/home/ubuntu/.local/lib/python3.13/site-packages/starlette/_exception_handler.py", line 51, in wrapped_app
    await app(scope, receive, sender)
  File "/home/ubuntu/.local/lib/python3.13/site-packages/starlette/routing.py", line 73, in app
    response = await f(request)
               ^^^^^^^^^^^^^^^^
  File "/home/ubuntu/.local/lib/python3.13/site-packages/fastapi/routing.py", line 301, in app
    raw_response = await run_endpoint_function(
                   ^^^^^^^^^^^^^^^^^^^^^^^^^^^^
    ...<3 lines>...
    )
    ^
  File "/home/ubuntu/.local/lib/python3.13/site-packages/fastapi/routing.py", line 214, in run_endpoint_function
    return await run_in_threadpool(dependant.call, **values)
           ^^^^^^^^^^^^^^^^^^^^^^^^^^^^^^^^^^^^^^^^^^^^^^^^^
  File "/home/ubuntu/.local/lib/python3.13/site-packages/starlette/concurrency.py", line 39, in run_in_threadpool
    return await anyio.to_thread.run_sync(func, *args)
           ^^^^^^^^^^^^^^^^^^^^^^^^^^^^^^^^^^^^^^^^^^^
  File "/home/ubuntu/.local/lib/python3.13/site-packages/anyio/to_thread.py", line 56, in run_sync
    return await get_async_backend().run_sync_in_worker_thread(
           ^^^^^^^^^^^^^^^^^^^^^^^^^^^^^^^^^^^^^^^^^^^^^^^^^^^^
        func, args, abandon_on_cancel=abandon_on_cancel, limiter=limiter
        ^^^^^^^^^^^^^^^^^^^^^^^^^^^^^^^^^^^^^^^^^^^^^^^^^^^^^^^^^^^^^^^^
    )
    ^
  File "/home/ubuntu/.local/lib/python3.13/site-packages/anyio/_backends/_asyncio.py", line 2476, in run_sync_in_worker_thread
    return await future
           ^^^^^^^^^^^^
  File "/home/ubuntu/.local/lib/python3.13/site-packages/anyio/_backends/_asyncio.py", line 967, in run
    result = context.run(func, *args)
  File "/workspace/orchestrator/app.py", line 1985, in create_task
    if DB_ENABLED and DB:
       ^^^^^^^^^^
NameError: name 'DB_ENABLED' is not defined
INFO:     127.0.0.1:59504 - "POST /tasks HTTP/1.1" 500 Internal Server Error
ERROR:    Exception in ASGI application
Traceback (most recent call last):
  File "/home/ubuntu/.local/lib/python3.13/site-packages/uvicorn/protocols/http/httptools_impl.py", line 401, in run_asgi
    result = await app(  # type: ignore[func-returns-value]
             ^^^^^^^^^^^^^^^^^^^^^^^^^^^^^^^^^^^^^^^^^^^^^^
        self.scope, self.receive, self.send
        ^^^^^^^^^^^^^^^^^^^^^^^^^^^^^^^^^^^
    )
    ^
  File "/home/ubuntu/.local/lib/python3.13/site-packages/uvicorn/middleware/proxy_headers.py", line 70, in __call__
    return await self.app(scope, receive, send)
           ^^^^^^^^^^^^^^^^^^^^^^^^^^^^^^^^^^^^
  File "/home/ubuntu/.local/lib/python3.13/site-packages/fastapi/applications.py", line 1054, in __call__
    await super().__call__(scope, receive, send)
  File "/home/ubuntu/.local/lib/python3.13/site-packages/starlette/applications.py", line 113, in __call__
    await self.middleware_stack(scope, receive, send)
  File "/home/ubuntu/.local/lib/python3.13/site-packages/starlette/middleware/errors.py", line 187, in __call__
    raise exc
  File "/home/ubuntu/.local/lib/python3.13/site-packages/starlette/middleware/errors.py", line 165, in __call__
    await self.app(scope, receive, _send)
  File "/home/ubuntu/.local/lib/python3.13/site-packages/starlette/middleware/exceptions.py", line 62, in __call__
    await wrap_app_handling_exceptions(self.app, conn)(scope, receive, send)
  File "/home/ubuntu/.local/lib/python3.13/site-packages/starlette/_exception_handler.py", line 62, in wrapped_app
    raise exc
  File "/home/ubuntu/.local/lib/python3.13/site-packages/starlette/_exception_handler.py", line 51, in wrapped_app
    await app(scope, receive, sender)
  File "/home/ubuntu/.local/lib/python3.13/site-packages/starlette/routing.py", line 715, in __call__
    await self.middleware_stack(scope, receive, send)
  File "/home/ubuntu/.local/lib/python3.13/site-packages/starlette/routing.py", line 735, in app
    await route.handle(scope, receive, send)
  File "/home/ubuntu/.local/lib/python3.13/site-packages/starlette/routing.py", line 288, in handle
    await self.app(scope, receive, send)
  File "/home/ubuntu/.local/lib/python3.13/site-packages/starlette/routing.py", line 76, in app
    await wrap_app_handling_exceptions(app, request)(scope, receive, send)
  File "/home/ubuntu/.local/lib/python3.13/site-packages/starlette/_exception_handler.py", line 62, in wrapped_app
    raise exc
  File "/home/ubuntu/.local/lib/python3.13/site-packages/starlette/_exception_handler.py", line 51, in wrapped_app
    await app(scope, receive, sender)
  File "/home/ubuntu/.local/lib/python3.13/site-packages/starlette/routing.py", line 73, in app
    response = await f(request)
               ^^^^^^^^^^^^^^^^
  File "/home/ubuntu/.local/lib/python3.13/site-packages/fastapi/routing.py", line 301, in app
    raw_response = await run_endpoint_function(
                   ^^^^^^^^^^^^^^^^^^^^^^^^^^^^
    ...<3 lines>...
    )
    ^
  File "/home/ubuntu/.local/lib/python3.13/site-packages/fastapi/routing.py", line 214, in run_endpoint_function
    return await run_in_threadpool(dependant.call, **values)
           ^^^^^^^^^^^^^^^^^^^^^^^^^^^^^^^^^^^^^^^^^^^^^^^^^
  File "/home/ubuntu/.local/lib/python3.13/site-packages/starlette/concurrency.py", line 39, in run_in_threadpool
    return await anyio.to_thread.run_sync(func, *args)
           ^^^^^^^^^^^^^^^^^^^^^^^^^^^^^^^^^^^^^^^^^^^
  File "/home/ubuntu/.local/lib/python3.13/site-packages/anyio/to_thread.py", line 56, in run_sync
    return await get_async_backend().run_sync_in_worker_thread(
           ^^^^^^^^^^^^^^^^^^^^^^^^^^^^^^^^^^^^^^^^^^^^^^^^^^^^
        func, args, abandon_on_cancel=abandon_on_cancel, limiter=limiter
        ^^^^^^^^^^^^^^^^^^^^^^^^^^^^^^^^^^^^^^^^^^^^^^^^^^^^^^^^^^^^^^^^
    )
    ^
  File "/home/ubuntu/.local/lib/python3.13/site-packages/anyio/_backends/_asyncio.py", line 2476, in run_sync_in_worker_thread
    return await future
           ^^^^^^^^^^^^
  File "/home/ubuntu/.local/lib/python3.13/site-packages/anyio/_backends/_asyncio.py", line 967, in run
    result = context.run(func, *args)
  File "/workspace/orchestrator/app.py", line 1985, in create_task
    if DB_ENABLED and DB:
       ^^^^^^^^^^
NameError: name 'DB_ENABLED' is not defined
WARNING:  WatchFiles detected changes in 'app.py'. Reloading...
INFO:     Shutting down
INFO:     Waiting for application shutdown.
INFO:     Application shutdown complete.
INFO:     Finished server process [9768]
INFO:     Started server process [14961]
INFO:     Waiting for application startup.
INFO:     Application startup complete.
WARNING:  WatchFiles detected changes in 'app.py'. Reloading...
INFO:     Shutting down
INFO:     Waiting for application shutdown.
INFO:     Application shutdown complete.
INFO:     Finished server process [14961]
INFO:     Started server process [15188]
INFO:     Waiting for application startup.
INFO:     Application startup complete.
ENV-CHECK: java:✔, aapt:✔, aapt2:✔, zipalign:✔, apksigner:✔, apktool:✔
INFO:     127.0.0.1:40116 - "POST /tasks HTTP/1.1" 500 Internal Server Error
ERROR:    Exception in ASGI application
Traceback (most recent call last):
  File "/home/ubuntu/.local/lib/python3.13/site-packages/uvicorn/protocols/http/httptools_impl.py", line 401, in run_asgi
    result = await app(  # type: ignore[func-returns-value]
             ^^^^^^^^^^^^^^^^^^^^^^^^^^^^^^^^^^^^^^^^^^^^^^
        self.scope, self.receive, self.send
        ^^^^^^^^^^^^^^^^^^^^^^^^^^^^^^^^^^^
    )
    ^
  File "/home/ubuntu/.local/lib/python3.13/site-packages/uvicorn/middleware/proxy_headers.py", line 70, in __call__
    return await self.app(scope, receive, send)
           ^^^^^^^^^^^^^^^^^^^^^^^^^^^^^^^^^^^^
  File "/home/ubuntu/.local/lib/python3.13/site-packages/fastapi/applications.py", line 1054, in __call__
    await super().__call__(scope, receive, send)
  File "/home/ubuntu/.local/lib/python3.13/site-packages/starlette/applications.py", line 113, in __call__
    await self.middleware_stack(scope, receive, send)
  File "/home/ubuntu/.local/lib/python3.13/site-packages/starlette/middleware/errors.py", line 187, in __call__
    raise exc
  File "/home/ubuntu/.local/lib/python3.13/site-packages/starlette/middleware/errors.py", line 165, in __call__
    await self.app(scope, receive, _send)
  File "/home/ubuntu/.local/lib/python3.13/site-packages/starlette/middleware/exceptions.py", line 62, in __call__
    await wrap_app_handling_exceptions(self.app, conn)(scope, receive, send)
  File "/home/ubuntu/.local/lib/python3.13/site-packages/starlette/_exception_handler.py", line 62, in wrapped_app
    raise exc
  File "/home/ubuntu/.local/lib/python3.13/site-packages/starlette/_exception_handler.py", line 51, in wrapped_app
    await app(scope, receive, sender)
  File "/home/ubuntu/.local/lib/python3.13/site-packages/starlette/routing.py", line 715, in __call__
    await self.middleware_stack(scope, receive, send)
  File "/home/ubuntu/.local/lib/python3.13/site-packages/starlette/routing.py", line 735, in app
    await route.handle(scope, receive, send)
  File "/home/ubuntu/.local/lib/python3.13/site-packages/starlette/routing.py", line 288, in handle
    await self.app(scope, receive, send)
  File "/home/ubuntu/.local/lib/python3.13/site-packages/starlette/routing.py", line 76, in app
    await wrap_app_handling_exceptions(app, request)(scope, receive, send)
  File "/home/ubuntu/.local/lib/python3.13/site-packages/starlette/_exception_handler.py", line 62, in wrapped_app
    raise exc
  File "/home/ubuntu/.local/lib/python3.13/site-packages/starlette/_exception_handler.py", line 51, in wrapped_app
    await app(scope, receive, sender)
  File "/home/ubuntu/.local/lib/python3.13/site-packages/starlette/routing.py", line 73, in app
    response = await f(request)
               ^^^^^^^^^^^^^^^^
  File "/home/ubuntu/.local/lib/python3.13/site-packages/fastapi/routing.py", line 301, in app
    raw_response = await run_endpoint_function(
                   ^^^^^^^^^^^^^^^^^^^^^^^^^^^^
    ...<3 lines>...
    )
    ^
  File "/home/ubuntu/.local/lib/python3.13/site-packages/fastapi/routing.py", line 214, in run_endpoint_function
    return await run_in_threadpool(dependant.call, **values)
           ^^^^^^^^^^^^^^^^^^^^^^^^^^^^^^^^^^^^^^^^^^^^^^^^^
  File "/home/ubuntu/.local/lib/python3.13/site-packages/starlette/concurrency.py", line 39, in run_in_threadpool
    return await anyio.to_thread.run_sync(func, *args)
           ^^^^^^^^^^^^^^^^^^^^^^^^^^^^^^^^^^^^^^^^^^^
  File "/home/ubuntu/.local/lib/python3.13/site-packages/anyio/to_thread.py", line 56, in run_sync
    return await get_async_backend().run_sync_in_worker_thread(
           ^^^^^^^^^^^^^^^^^^^^^^^^^^^^^^^^^^^^^^^^^^^^^^^^^^^^
        func, args, abandon_on_cancel=abandon_on_cancel, limiter=limiter
        ^^^^^^^^^^^^^^^^^^^^^^^^^^^^^^^^^^^^^^^^^^^^^^^^^^^^^^^^^^^^^^^^
    )
    ^
  File "/home/ubuntu/.local/lib/python3.13/site-packages/anyio/_backends/_asyncio.py", line 2476, in run_sync_in_worker_thread
    return await future
           ^^^^^^^^^^^^
  File "/home/ubuntu/.local/lib/python3.13/site-packages/anyio/_backends/_asyncio.py", line 967, in run
    result = context.run(func, *args)
  File "/workspace/orchestrator/app.py", line 1985, in create_task
    if DB_ENABLED and DB:
       ^^^^^^^^^^
NameError: name 'DB_ENABLED' is not defined
INFO:     127.0.0.1:47068 - "POST /tasks HTTP/1.1" 500 Internal Server Error
ERROR:    Exception in ASGI application
Traceback (most recent call last):
  File "/home/ubuntu/.local/lib/python3.13/site-packages/uvicorn/protocols/http/httptools_impl.py", line 401, in run_asgi
    result = await app(  # type: ignore[func-returns-value]
             ^^^^^^^^^^^^^^^^^^^^^^^^^^^^^^^^^^^^^^^^^^^^^^
        self.scope, self.receive, self.send
        ^^^^^^^^^^^^^^^^^^^^^^^^^^^^^^^^^^^
    )
    ^
  File "/home/ubuntu/.local/lib/python3.13/site-packages/uvicorn/middleware/proxy_headers.py", line 70, in __call__
    return await self.app(scope, receive, send)
           ^^^^^^^^^^^^^^^^^^^^^^^^^^^^^^^^^^^^
  File "/home/ubuntu/.local/lib/python3.13/site-packages/fastapi/applications.py", line 1054, in __call__
    await super().__call__(scope, receive, send)
  File "/home/ubuntu/.local/lib/python3.13/site-packages/starlette/applications.py", line 113, in __call__
    await self.middleware_stack(scope, receive, send)
  File "/home/ubuntu/.local/lib/python3.13/site-packages/starlette/middleware/errors.py", line 187, in __call__
    raise exc
  File "/home/ubuntu/.local/lib/python3.13/site-packages/starlette/middleware/errors.py", line 165, in __call__
    await self.app(scope, receive, _send)
  File "/home/ubuntu/.local/lib/python3.13/site-packages/starlette/middleware/exceptions.py", line 62, in __call__
    await wrap_app_handling_exceptions(self.app, conn)(scope, receive, send)
  File "/home/ubuntu/.local/lib/python3.13/site-packages/starlette/_exception_handler.py", line 62, in wrapped_app
    raise exc
  File "/home/ubuntu/.local/lib/python3.13/site-packages/starlette/_exception_handler.py", line 51, in wrapped_app
    await app(scope, receive, sender)
  File "/home/ubuntu/.local/lib/python3.13/site-packages/starlette/routing.py", line 715, in __call__
    await self.middleware_stack(scope, receive, send)
  File "/home/ubuntu/.local/lib/python3.13/site-packages/starlette/routing.py", line 735, in app
    await route.handle(scope, receive, send)
  File "/home/ubuntu/.local/lib/python3.13/site-packages/starlette/routing.py", line 288, in handle
    await self.app(scope, receive, send)
  File "/home/ubuntu/.local/lib/python3.13/site-packages/starlette/routing.py", line 76, in app
    await wrap_app_handling_exceptions(app, request)(scope, receive, send)
  File "/home/ubuntu/.local/lib/python3.13/site-packages/starlette/_exception_handler.py", line 62, in wrapped_app
    raise exc
  File "/home/ubuntu/.local/lib/python3.13/site-packages/starlette/_exception_handler.py", line 51, in wrapped_app
    await app(scope, receive, sender)
  File "/home/ubuntu/.local/lib/python3.13/site-packages/starlette/routing.py", line 73, in app
    response = await f(request)
               ^^^^^^^^^^^^^^^^
  File "/home/ubuntu/.local/lib/python3.13/site-packages/fastapi/routing.py", line 301, in app
    raw_response = await run_endpoint_function(
                   ^^^^^^^^^^^^^^^^^^^^^^^^^^^^
    ...<3 lines>...
    )
    ^
  File "/home/ubuntu/.local/lib/python3.13/site-packages/fastapi/routing.py", line 214, in run_endpoint_function
    return await run_in_threadpool(dependant.call, **values)
           ^^^^^^^^^^^^^^^^^^^^^^^^^^^^^^^^^^^^^^^^^^^^^^^^^
  File "/home/ubuntu/.local/lib/python3.13/site-packages/starlette/concurrency.py", line 39, in run_in_threadpool
    return await anyio.to_thread.run_sync(func, *args)
           ^^^^^^^^^^^^^^^^^^^^^^^^^^^^^^^^^^^^^^^^^^^
  File "/home/ubuntu/.local/lib/python3.13/site-packages/anyio/to_thread.py", line 56, in run_sync
    return await get_async_backend().run_sync_in_worker_thread(
           ^^^^^^^^^^^^^^^^^^^^^^^^^^^^^^^^^^^^^^^^^^^^^^^^^^^^
        func, args, abandon_on_cancel=abandon_on_cancel, limiter=limiter
        ^^^^^^^^^^^^^^^^^^^^^^^^^^^^^^^^^^^^^^^^^^^^^^^^^^^^^^^^^^^^^^^^
    )
    ^
  File "/home/ubuntu/.local/lib/python3.13/site-packages/anyio/_backends/_asyncio.py", line 2476, in run_sync_in_worker_thread
    return await future
           ^^^^^^^^^^^^
  File "/home/ubuntu/.local/lib/python3.13/site-packages/anyio/_backends/_asyncio.py", line 967, in run
    result = context.run(func, *args)
  File "/workspace/orchestrator/app.py", line 1985, in create_task
    if DB_ENABLED and DB:
       ^^^^^^^^^^
NameError: name 'DB_ENABLED' is not defined
